<robot name="friday">
  <link name="waist_5">
    <inertial>
      <origin xyz="1.35732334303223E-05 0.135898614953202 -0.0188496042510568" rpy="0 0 0" />
      <mass value="12.474122580364" />
      <inertia ixx="0.109178941754524" ixy="-2.98129835492946E-05" ixz="-3.19150484404308E-06" iyy="0.107169406583023" iyz="-0.00214461668880564" izz="0.157827782829379" />
    </inertial>
    <visual>
      <origin xyz="0 0 0" rpy="0 0 0" />
      <geometry>
        <mesh filename="../meshes/friday/visual/body.obj" />
      </geometry>
    </visual>
    <visual>
      <origin xyz="0 -0.006322245945349 0" rpy="0 0 0" />
      <geometry>
        <mesh filename="../meshes/friday/visual/body_backpack.obj" />
      </geometry>
    </visual>
    <visual>
      <origin xyz="0 0.194843979673063 0" rpy="0 0 0" />
      <geometry>
        <mesh filename="../meshes/friday/visual/body_logo.obj" />
      </geometry>
    </visual>
    <collision>
      <origin xyz="0 0 0" rpy="0 0 0" />
      <geometry>
        <mesh filename="../meshes/friday/collision/compact_waist_5.obj" />
      </geometry>
    </collision>
  </link>
  <link name="right_arm_1">
    <inertial>
      <origin xyz="-0.0504783902306926 0.00890129178533927 -0.00679453644214538" rpy="0 0 0" />
      <mass value="0.651474546540579" />
      <inertia ixx="0.000731842888672747" ixy="3.59742635586591E-05" ixz="-3.81367597786363E-05" iyy="0.000929468035003683" iyz="6.73422556956025E-06" izz="0.000892686460138007" />
    </inertial>
    <visual>
      <origin xyz="0 0 0" rpy="0 0 0" />
      <geometry>
        <mesh filename="../meshes/friday/visual/right_arm_1.obj" />
      </geometry>
    </visual>
  </link>
  <joint name="right_arm_1" type="revolute">
    <origin xyz="-0.172029404471144 0.231163071735731 0" rpy="0 0 0" />
    <parent link="waist_5" />
    <child link="right_arm_1" />
    <axis xyz="-0.984807753012208 0.173648177666932 0" />
    <limit effort="87.0" lower="-0.4236" upper="2.5180" velocity="2.0" />
  </joint>
  <link name="right_arm_2">
    <inertial>
      <origin xyz="-0.00876610551709145 -0.0838925972250821 -0.000116637744680237" rpy="0 0 0" />
      <mass value="0.552803787561506" />
      <inertia ixx="0.000519188555883051" ixy="-8.90912453909685E-06" ixz="1.5759114172996E-06" iyy="0.000459209519989159" iyz="8.14107358177029E-06" izz="0.000544537600281593" />
    </inertial>
    <visual>
      <origin xyz="0 0 0" rpy="0 0 0" />
      <geometry>
        <mesh filename="../meshes/friday/visual/right_arm_2.obj" />
      </geometry>
    </visual>
    <collision>
      <origin xyz="0 0 0" rpy="0 0 0" />
      <geometry>
        <mesh filename="../meshes/friday/collision/compact_right_arm_2.obj" />
      </geometry>
    </collision>
  </link>
  <joint name="right_arm_2" type="revolute">
    <origin xyz="-0.0590971787351876 0.0104204270947499 0" rpy="0 0 0" />
    <parent link="right_arm_1" />
    <child link="right_arm_2" />
    <axis xyz="0 0 -1" />
    <limit effort="87.0" lower="0.0" upper="2.2562" velocity="2.0" />
  </joint>
  <link name="right_arm_3">
    <inertial>
      <origin xyz="-0.000133731452946151 -0.0679041256616604 -0.0020044978911568" rpy="0 0 0" />
      <mass value="0.726149922961283" />
      <inertia ixx="0.00135809777973873" ixy="-5.89216930081264E-06" ixz="1.34889818650324E-06" iyy="0.000527337663742348" iyz="-3.44595442111269E-05" izz="0.00136476731130073" />
    </inertial>
    <visual>
      <origin xyz="0 0 0" rpy="0 0 0" />
      <geometry>
        <mesh filename="../meshes/friday/visual/right_arm_3.obj" />
      </geometry>
    </visual>
    <collision>
      <origin xyz="0 -0.1 0.0" rpy="0 0 0" />
      <geometry>
				<box size="0.065 0.08 0.06" />
			</geometry>
    </collision>
  </link>
  <joint name="right_arm_3" type="revolute">
    <origin xyz="-0.0100000000000191 -0.136500000000018 0" rpy="0 0 0" />
    <parent link="right_arm_2" />
    <child link="right_arm_3" />
    <axis xyz="0 -1 0" />
    <limit effort="87.0" lower="-1.4708" upper="1.4708" velocity="2.0" />
  </joint>
  <link name="right_arm_4">
    <inertial>
      <origin xyz="-2.76445533131664E-14 -0.045952576906095 -0.0136740346459322" rpy="0 0 0" />
      <mass value="0.467228469256572" />
      <inertia ixx="0.000771988372959408" ixy="1.94600978543822E-16" ixz="4.31013975029117E-12" iyy="0.000278940153191588" iyz="4.81484159713596E-06" izz="0.000775309371405241" />
    </inertial>
    <visual>
      <origin xyz="0 0 0" rpy="0 0 0" />
      <geometry>
        <mesh filename="../meshes/friday/visual/right_arm_4.obj" />
      </geometry>
    </visual>
    <collision>
      <origin xyz="0 0 0" rpy="0 0 0" />
      <geometry>
        <mesh filename="../meshes/friday/collision/compact_right_arm_4.obj" />
      </geometry>
    </collision>
  </link>
  <joint name="right_arm_4" type="revolute">
    <origin xyz="0 -0.13 0.0134999999984212" rpy="0 0 0" />
    <parent link="right_arm_3" />
    <child link="right_arm_4" />
    <axis xyz="-1 0 0" />
    <limit effort="87.0" lower="0.0" upper="2.1689" velocity="2.0" />
  </joint>
  <link name="right_arm_5">
    <inertial>
      <origin xyz="5.77929130494981E-05 -2.10908799249993E-05 0.0303745916076382" rpy="0 0 0" />
      <mass value="0.141645120498882" />
      <inertia ixx="0.000150674876586753" ixy="-9.98797795815426E-06" ixz="-9.93466915122478E-08" iyy="0.00015148916187729" iyz="8.09491309586898E-08" izz="7.93773197761316E-05" />
    </inertial>
    <visual>
      <origin xyz="0 0 0" rpy="0 0 0" />
      <geometry>
        <mesh filename="../meshes/friday/visual/right_arm_5.obj" />
      </geometry>
    </visual>
    <collision>
      <origin xyz="0 0 0" rpy="0 0 0" />
      <geometry>
        <mesh filename="../meshes/friday/collision/compact_right_arm_5.obj" />
      </geometry>
    </collision>
  </link>
  <joint name="right_arm_5" type="revolute">
    <origin xyz="0 -0.10259999999999 -0.0134999999984212" rpy="1.5707963267949 0 0" />
    <parent link="right_arm_4" />
    <child link="right_arm_5" />
    <axis xyz="0 0 1" />
    <limit effort="87.0" lower="-1.4708" upper="1.4708" velocity="2.0" />
  </joint>
  <link name="right_arm_6">
    <inertial>
      <origin xyz="-8.14545597892236E-05 7.51009215400755E-05 0.0117608666205656" rpy="0 0 0" />
      <mass value="0.0314621801352106" />
      <inertia ixx="7.82929735327741E-06" ixy="1.10612506401232E-08" ixz="1.46345904053749E-08" iyy="8.71321796162152E-06" iyz="-7.15856215621043E-09" izz="7.73497403513718E-06" />
    </inertial>
    <visual>
      <origin xyz="0 0 0" rpy="0 0 0" />
      <geometry>
        <mesh filename="../meshes/friday/visual/right_arm_6.obj" />
      </geometry>
    </visual>
  </link>
  <joint name="right_arm_6" type="revolute">
    <origin xyz="0 0 0.111999999999983" rpy="0 0 0" />
    <parent link="right_arm_5" />
    <child link="right_arm_6" />
    <axis xyz="0 -1 0" />
    <limit effort="87.0" lower="-0.9472" upper="0.9472" velocity="2.0" />
  </joint>
  <link name="right_arm_7">
    <inertial>
      <origin xyz="0.00155644949116443 0.00311722917436926 0.0509010500036021" rpy="0 0 0" />
      <mass value="0.131756699270941" />
      <inertia ixx="7.77647231616779E-05" ixy="-8.79445374853935E-07" ixz="8.86916310181377E-07" iyy="3.25934806046904E-05" iyz="-6.93098580275756E-06" izz="5.59120417690713E-05" />
    </inertial>
    <visual>
      <origin xyz="0 0 0" rpy="0 0 0" />
      <geometry>
        <mesh filename="../meshes/friday/visual/right_arm_7.obj" />
      </geometry>
    </visual>
    <collision>
      <origin xyz="0 0 0" rpy="0 0 0" />
      <geometry>
        <mesh filename="../meshes/friday/collision/compact_right_arm_7.obj" />
      </geometry>
    </collision>
  </link>
  <joint name="right_arm_7" type="revolute">
    <origin xyz="0 0 0.0400000000000003" rpy="0 0 0" />
    <parent link="right_arm_6" />
    <child link="right_arm_7" />
    <axis xyz="-1 0 0" />
    <limit effort="87.0" lower="-0.6854" upper="0.6854" velocity="2.0" />
  </joint>
  <link name="ball_link">
      <visual>
      <material name="red">
          <color rgba="1 0 0 1"/>
      </material>

      <geometry>
          <sphere radius="0.01"/>
      </geometry>
      </visual>
  </link>
  <joint name="ball_joint" type="fixed">
      <origin rpy="0.0 0.0 0.0" xyz="0.09566 0 0.021" />
      <parent link="right_arm_7"/>
      <child link="ball_link"/>
  </joint>
</robot>