<?xml version='1.0' encoding='utf-8'?>
<robot name="friday">
  <link name="BASE">
    <inertial>
      <origin xyz="1.75045845306481E-05 -0.0042584914937362 0.032751912864302" rpy="0 0 0" />
      <mass value="74.7754001395149" />
      <inertia ixx="2.58737420092528" ixy="0.000319763914205704" ixz="0.000155649863391633" iyy="2.1055877773509" iyz="3.60872462717528E-05" izz="4.02907932324286" />
    </inertial>
    <visual>
      <origin xyz="0 0 0" rpy="0 0 0" />
      <geometry>
        <mesh filename="../meshes/friday/visual/BASE2.obj" />
      </geometry>
    </visual>
    <collision>
      <origin xyz="0 0 0" rpy="0 0 0" />
      <geometry>
        <mesh filename="../meshes/friday/collision/compact_BASE2.obj" />
      </geometry>
    </collision>
  </link>
  <link name="waist_1">
    <inertial>
      <origin xyz="1.16545498811958E-05 -0.068703685171536 -0.00907875870547078" rpy="0 0 0" />
      <mass value="2.28030239046852" />
      <inertia ixx="0.00938983160742122" ixy="-9.57396840435693E-08" ixz="-1.29986940084323E-08" iyy="0.00808066260606062" iyz="-0.000338202732338668" izz="0.00767734180794995" />
    </inertial>
    <visual>
      <origin xyz="0 0 0" rpy="0 0 0" />
      <geometry>
        <mesh filename="../meshes/friday/visual/waist_1.obj" />
      </geometry>
    </visual>
  </link>
  <joint name="waist_1" type="revolute">
    <origin xyz="0 0 0.0774999999999989" rpy="-1.5707963267949 0 -1.5707963267949" />
    <parent link="BASE" />
    <child link="waist_1" />
    <axis xyz="0 -1 0" />
    <limit effort="87.0" lower="-6.0087" upper="6.0087" velocity="2.0" />
  </joint>
  <link name="waist_2">
    <inertial>
      <origin xyz="0.169082106254835 -0.0296856886812593 0.000715493177378996" rpy="0 0 0" />
      <mass value="6.67250483745669" />
      <inertia ixx="0.0221283200291127" ixy="0.0266521068026327" ixz="-8.29917274310648E-06" iyy="0.141192327418972" iyz="3.96021662629429E-05" izz="0.147101845367497" />
    </inertial>
    <visual>
      <origin xyz="0 0 0" rpy="0 0 0" />
      <geometry>
        <mesh filename="../meshes/friday/visual/waist_2.obj" />
      </geometry>
    </visual>
    <collision>
      <origin xyz="0 0 0" rpy="0 0 0" />
      <geometry>
        <mesh filename="../meshes/friday/collision/compact_waist_2_1.obj" />
      </geometry>
    </collision>
    <collision>
      <origin xyz="0 0 0" rpy="0 0 0" />
      <geometry>
        <mesh filename="../meshes/friday/collision/compact_waist_2_2.obj" />
      </geometry>
    </collision>
  </link>
  <joint name="waist_2" type="revolute">
    <origin xyz="0 -0.1675 0" rpy="3.14159265358979 0 -1.5707963267949" />
    <parent link="waist_1" />
    <child link="waist_2" />
    <axis xyz="0 0 -1" />
    <limit effort="87.0" lower="-1.4708" upper="0.9472" velocity="2.0" />
  </joint>
  <link name="waist_3">
    <inertial>
      <origin xyz="0.00535037350931574 0.0500812139106874 0.163085401390087" rpy="0 0 0" />
      <mass value="1.70152759023929" />
      <inertia ixx="0.0275384939046975" ixy="0.000130702093349402" ixz="-4.02983023309186E-05" iyy="0.0316164870500356" iyz="-0.00332531557318982" izz="0.0112086032936333" />
    </inertial>
    <visual>
      <origin xyz="0 0 0" rpy="0 0 0" />
      <geometry>
        <mesh filename="../meshes/friday/visual/waist_3.obj" />
      </geometry>
    </visual>
    <collision>
      <origin xyz="0 0.06 0.18" rpy="0 0 0" />
      <geometry>
				<box size="0.16 0.11 0.18" />
			</geometry>
    </collision>
  </link>
  <joint name="waist_3" type="revolute">
    <origin xyz="0.341648942630047 -0.0759999999984945 0" rpy="0 1.5707963267949 0" />
    <parent link="waist_2" />
    <child link="waist_3" />
    <axis xyz="1 0 0" />
    <limit effort="87.0" lower="-0.9472" upper="2.5529" velocity="2.0" />
  </joint>
  <link name="waist_4">
    <inertial>
      <origin xyz="-0.00071731831191072 0.0425495832711386 -0.000129214471411725" rpy="0 0 0" />
      <mass value="3.37789013540646" />
      <inertia ixx="0.0167315874475137" ixy="-0.000116046136005172" ixz="-3.80024047608918E-08" iyy="0.00847737566268671" iyz="1.66617758394331E-06" izz="0.0161301323365026" />
    </inertial>
    <visual>
      <origin xyz="0 0 0" rpy="0 0 0" />
      <geometry>
        <mesh filename="../meshes/friday/visual/waist_4.obj" />
      </geometry>
    </visual>
    <collision>
      <origin xyz="0 0 0" rpy="0 0 0" />
      <geometry>
        <mesh filename="../meshes/friday/collision/compact_waist_4.obj" />
      </geometry>
    </collision>
  </link>
  <joint name="waist_4" type="revolute">
    <origin xyz="0 0.0759999999984945 0.341648942629712" rpy="1.5707963267949 0 0" />
    <parent link="waist_3" />
    <child link="waist_4" />
    <axis xyz="1 0 0" />
    <limit effort="87.0" lower="-1.7326" upper="0.9472" velocity="2.0" />
  </joint>
  <link name="waist_5">
    <inertial>
      <origin xyz="1.35732334303223E-05 0.135898614953202 -0.0188496042510568" rpy="0 0 0" />
      <mass value="12.474122580364" />
      <inertia ixx="0.109178941754524" ixy="-2.98129835492946E-05" ixz="-3.19150484404308E-06" iyy="0.107169406583023" iyz="-0.00214461668880564" izz="0.157827782829379" />
    </inertial>
    <visual>
      <origin xyz="0 0 0" rpy="0 0 0" />
      <geometry>
        <mesh filename="../meshes/friday/visual/body.obj" />
      </geometry>
    </visual>
    <visual>
      <origin xyz="0 -0.006322245945349 0" rpy="0 0 0" />
      <geometry>
        <mesh filename="../meshes/friday/visual/body_backpack.obj" />
      </geometry>
    </visual>
    <visual>
      <origin xyz="0 0.194843979673063 0" rpy="0 0 0" />
      <geometry>
        <mesh filename="../meshes/friday/visual/body_logo.obj" />
      </geometry>
    </visual>
    <collision>
      <origin xyz="0 0 0" rpy="0 0 0" />
      <geometry>
        <mesh filename="../meshes/friday/collision/compact_waist_5.obj" />
      </geometry>
    </collision>
  </link>
  <joint name="waist_5" type="revolute">
    <origin xyz="0 0.141999999999935 0" rpy="0 0 0" />
    <parent link="waist_4" />
    <child link="waist_5" />
    <axis xyz="0 1 0" />
    <limit effort="87.0" lower="-5.9388" upper="5.9388" velocity="2.0" />
  </joint>

  <link name="left_arm_1">
    <inertial>
      <origin xyz="0.0681778315832787 0.0120221796894002 -0.0067812975431665" rpy="0 0 0" />
      <mass value="0.65274639829115" />
      <inertia ixx="0.000734648467001504" ixy="-3.62701010648506E-05" ixz="3.85551694833418E-05" iyy="0.000933899014758635" iyz="6.8080075629328E-06" izz="0.000897118604744115" />
    </inertial>
    <visual>
      <origin xyz="0 0 0" rpy="0 0 0" />
      <geometry>
        <mesh filename="../meshes/friday/visual/left_arm_1.obj" />
      </geometry>
    </visual>
  </link>
  <joint name="left_arm_1" type="revolute">
    <!-- <origin xyz="0.144387358602375 0.226289035459258 0" rpy="0 0 0" /> -->
    <origin xyz="0.154235438602375 0.228025515459258 0" rpy="0 0 0" />
    <parent link="waist_5" />
    <child link="left_arm_1" />
    <axis xyz="-0.984807753012208 -0.173648177666932 0" />
    <limit effort="87.0" lower="-0.4236" upper="2.5180" velocity="2.0" />
  </joint>
  <link name="left_arm_2">
    <inertial>
      <origin xyz="0.00876610230499331 -0.0838600339221796 -0.000115821686215815" rpy="0 0 0" />
      <mass value="0.552470086721825" />
      <inertia ixx="0.000518419495011146" ixy="8.92509610843467E-06" ixz="-1.59111934775713E-06" iyy="0.00045867874968829" iyz="8.16013558251578E-06" izz="0.000543758567127829" />
    </inertial>
    <visual>
      <origin xyz="0 0 0" rpy="0 0 0" />
      <geometry>
        <mesh filename="../meshes/friday/visual/left_arm_2.obj" />
      </geometry>
    </visual>
    <collision>
      <origin xyz="0 0 0" rpy="0 0 0" />
      <geometry>
        <mesh filename="../meshes/friday/collision/compact_left_arm_2.obj" />
      </geometry>
    </collision>
  </link>
  <joint name="left_arm_2" type="revolute">
    <origin xyz="0.076891144603957 0.0135579833712227 0" rpy="0 0 0" />
    <parent link="left_arm_1" />
    <child link="left_arm_2" />
    <axis xyz="0 0 1" />
    <limit effort="87.0" lower="0.0" upper="2.2562" velocity="2.0" />
  </joint>
  <link name="left_arm_3">
    <inertial>
      <origin xyz="0.000140505415812536 -0.0647204132155317 -0.00150532371572329" rpy="0 0 0" />
      <mass value="0.641686932437179" />
      <inertia ixx="0.00131223395207345" ixy="5.88564128440786E-06" ixz="-1.35288724944641E-06" iyy="0.000496471588137728" iyz="-3.56318015097049E-05" izz="0.00132692863229049" />
    </inertial>
    <visual>
      <origin xyz="0 0 0" rpy="0 0 0" />
      <geometry>
        <mesh filename="../meshes/friday/visual/left_arm_3.obj" />
      </geometry>
    </visual>
    <collision>
      <origin xyz="0 -0.1 0.0" rpy="0 0 0" />
      <geometry>
				<box size="0.065 0.08 0.06" />
			</geometry>
    </collision>
  </link>
  <joint name="left_arm_3" type="revolute">
    <origin xyz="0.0100000000000251 -0.136500000000012 0" rpy="0 0 0" />
    <parent link="left_arm_2" />
    <child link="left_arm_3" />
    <axis xyz="0 1 0" />
    <limit effort="87.0" lower="-1.4708" upper="1.4708" velocity="2.0" />
  </joint>
  <link name="left_arm_4">
    <inertial>
      <origin xyz="-3.35287353436797E-14 -0.0459525747799207 -0.0136740346354466" rpy="0 0 0" />
      <mass value="0.467228497737904" />
      <inertia ixx="0.000771988413929587" ixy="1.77253719440116E-17" ixz="-1.0656151900853E-11" iyy="0.000278940154315871" iyz="4.81484142200182E-06" izz="0.000775309381777704" />
    </inertial>
    <visual>
      <origin xyz="0 0 0" rpy="0 0 0" />
      <geometry>
        <mesh filename="../meshes/friday/visual/left_arm_4.obj" />
      </geometry>
    </visual>
    <collision>
      <origin xyz="0 0 0" rpy="0 0 0" />
      <geometry>
        <mesh filename="../meshes/friday/collision/compact_left_arm_4.obj" />
      </geometry>
    </collision>
  </link>
  <joint name="left_arm_4" type="revolute">
    <origin xyz="0 -0.129999999999999 0.013499999998509" rpy="0 0 0" />
    <parent link="left_arm_3" />
    <child link="left_arm_4" />
    <axis xyz="-1 0 0" />
    <limit effort="87.0" lower="0.0" upper="2.1689" velocity="2.0" />
  </joint>
  <link name="left_arm_5">
    <inertial>
      <origin xyz="5.77929163333712E-05 -2.10908777993994E-05 0.0303745916212222" rpy="0 0 0" />
      <mass value="0.141645120451258" />
      <inertia ixx="0.000150674876659959" ixy="-9.98797795493656E-06" ixz="-9.93466740338049E-08" iyy="0.00015148916195091" iyz="8.09491425900871E-08" izz="7.9377319772219E-05" />
    </inertial>
    <visual>
      <origin xyz="0 0 0" rpy="0 0 0" />
      <geometry>
        <mesh filename="../meshes/friday/visual/left_arm_5.obj" />
      </geometry>
    </visual>
    <collision>
      <origin xyz="0 0 0" rpy="0 0 0" />
      <geometry>
        <mesh filename="../meshes/friday/collision/compact_left_arm_5.obj" />
      </geometry>
    </collision>
  </link>
  <joint name="left_arm_5" type="revolute">
    <origin xyz="0 -0.102599999999996 -0.013499999998509" rpy="1.5707963267949 0 0" />
    <parent link="left_arm_4" />
    <child link="left_arm_5" />
    <axis xyz="0 0 -1" />
    <limit effort="87.0" lower="-1.4708" upper="1.4708" velocity="2.0" />
  </joint>
  <link name="left_arm_6">
    <inertial>
      <origin xyz="-8.14545597854766E-05 7.51009215384403E-05 0.0117608666205666" rpy="0 0 0" />
      <mass value="0.0314621801352106" />
      <inertia ixx="7.82929735327746E-06" ixy="1.1061250640138E-08" ixz="1.46345904053749E-08" iyy="8.7132179616215E-06" iyz="-7.15856215622018E-09" izz="7.73497403513724E-06" />
    </inertial>
    <visual>
      <origin xyz="0 0 0" rpy="0 0 0" />
      <geometry>
        <mesh filename="../meshes/friday/visual/left_arm_6.obj" />
      </geometry>
    </visual>
  </link>
  <joint name="left_arm_6" type="revolute">
    <origin xyz="0 0 0.111999999999982" rpy="0 0 0" />
    <parent link="left_arm_5" />
    <child link="left_arm_6" />
    <axis xyz="0 1 0" />
    <limit effort="87.0" lower="-0.9472" upper="0.9472" velocity="2.0" />
  </joint>
  <link name="left_arm_7">
    <inertial>
      <origin xyz="0.0015564769305858 0.0031171837162328 -0.0509003091661051" rpy="0 0 0" />
      <mass value="0.131752288131971" />
      <inertia ixx="7.77640623933446E-05" ixy="-8.79352768144738E-07" ixz="-8.87560258478892E-07" iyy="3.25935847362588E-05" iyz="6.93151713655908E-06" izz="5.59108691824527E-05" />
    </inertial>
    <visual>
      <origin xyz="0 0 0" rpy="0 0 0" />
      <geometry>
        <mesh filename="../meshes/friday/visual/left_arm_7.obj" />
      </geometry>
    </visual>
    <collision>
      <origin xyz="0 0 0" rpy="0 0 0" />
      <geometry>
        <mesh filename="../meshes/friday/collision/compact_left_arm_7.obj" />
      </geometry>
    </collision>
  </link>
  <joint name="left_arm_7" type="revolute">
    <origin xyz="0 0 0.040000000000001" rpy="3.14159265358979 0 3.14159265358979" />
    <parent link="left_arm_6" />
    <child link="left_arm_7" />
    <axis xyz="1 0 0" />
    <limit effort="87.0" lower="-0.6854" upper="0.6854" velocity="2.0" />
  </joint>
  <joint name="ball_joint" type="fixed">
      <origin rpy="0.0 0.0 0.0" xyz="0.09566 0 -0.021" />
      <parent link="left_arm_7"/>
      <child link="ball_link"/>
  </joint>
  <link name="ball_link">
      <visual>
      <material name="red">
          <color rgba="1 0 0 1"/>
      </material>

      <geometry>
          <sphere radius="0.01"/>
      </geometry>
      </visual>
  </link>
  <link name="left_finger_1_1">
    <inertial>
      <origin xyz="0.0039242021041771 0.0136427276962503 -0.00414365904540503" rpy="0 0 0" />
      <mass value="0.00772716094800163" />
      <inertia ixx="1.10265269291336E-06" ixy="-8.47560082286645E-08" ixz="-9.23101802218766E-09" iyy="6.86430772220065E-07" iyz="2.33631760999272E-07" izz="5.92242751171146E-07" />
    </inertial>
    <visual>
      <origin xyz="0 0 0" rpy="0 0 0" />
      <geometry>
        <mesh filename="../meshes/friday/visual/left_finger_1_1.obj" />
      </geometry>
    </visual>
    <collision>
      <origin xyz="0 0 0" rpy="0 0 0" />
      <geometry>
        <mesh filename="../meshes/friday/collision/compact_left_finger_1_1.obj" />
      </geometry>
    </collision>
  </link>
  <joint name="left_finger_1_1" type="revolute">
    <origin xyz="0.0130000000000054 0.031577262848049 -0.0477824821132676" rpy="0 0 0" />
    <parent link="left_arm_7" />
    <child link="left_finger_1_1" />
    <axis xyz="0 0.37460659342004 -0.92718385456512" />
    <limit effort="87.0" lower="0.0" upper="1.5708" velocity="2.0" />
  </joint>
  <link name="left_finger_1_2">
    <inertial>
      <origin xyz="0.00193519578983328 0.00296049205136077 0.00850419854514783" rpy="0 0 0" />
      <mass value="0.00174087633242516" />
      <inertia ixx="1.48559406813772E-07" ixy="-9.36026436682074E-09" ixz="1.21227663067357E-08" iyy="1.23940912343442E-07" iyz="4.17640610994023E-08" izz="6.90659715168832E-08" />
    </inertial>
    <visual>
      <origin xyz="0 0 0" rpy="0 0 0" />
      <geometry>
        <mesh filename="../meshes/friday/visual/left_finger_1_2.obj" />
      </geometry>
    </visual>
  </link>
  <joint name="left_finger_1_2" type="revolute">
    <origin xyz="0.00255010042322423 0.0286948142815488 -0.0171767671991525" rpy="0 0 0" />
    <parent link="left_finger_1_1" />
    <child link="left_finger_1_2" />
    <axis xyz="-0.657098606720372 -0.343316547187274 -0.671085068730898" />
    <limit effort="87.0" lower="0.0" upper="1.5708" velocity="2.0" />
  </joint>
  <link name="left_finger_1_3">
    <inertial>
      <origin xyz="0.00209450835800074 0.0125724889868159 -0.00801681952062394" rpy="0 0 0" />
      <mass value="0.00668476820933792" />
      <inertia ixx="5.90545333693761E-07" ixy="-6.08091782798472E-08" ixz="-2.42695120372568E-08" iyy="4.02056523552086E-07" iyz="1.49273604527104E-07" izz="4.75029313734924E-07" />
    </inertial>
    <visual>
      <origin xyz="0 0 0" rpy="0 0 0" />
      <geometry>
        <mesh filename="../meshes/friday/visual/left_finger_1_3.obj" />
      </geometry>
    </visual>
    <collision>
      <origin xyz="0 0 0" rpy="0 0 0" />
      <geometry>
        <mesh filename="../meshes/friday/collision/compact_left_finger_1_3.obj" />
      </geometry>
    </collision>
  </link>
  <joint name="left_finger_1_3" type="revolute">
    <origin xyz="0.00483379709394355 0.00874788690831656 -0.0020484229551494" rpy="0 0 0" />
    <parent link="left_finger_1_2" />
    <child link="left_finger_1_3" />
    <axis xyz="-0.730425975909756 0.509989436085111 0.45430019678388" />
    <limit effort="87.0" lower="0.0" upper="1.047" velocity="2.0" />
  </joint>
  <link name="left_finger_1_4">
    <inertial>
      <origin xyz="0.000700433654984567 0.0132146095826828 -0.00679049845127" rpy="0 0 0" />
      <mass value="0.00756286683975585" />
      <inertia ixx="6.55166568355822E-07" ixy="-5.94295731131225E-08" ixz="-3.45662557543245E-08" iyy="3.76348763546946E-07" iyz="1.66815716284291E-07" izz="5.37305926227873E-07" />
    </inertial>
    <visual>
      <origin xyz="0 0 0" rpy="0 0 0" />
      <geometry>
        <mesh filename="../meshes/friday/visual/left_finger_1_4.obj" />
      </geometry>
    </visual>
    <collision>
      <origin xyz="0 0 0" rpy="0 0 0" />
      <geometry>
        <mesh filename="../meshes/friday/collision/compact_left_finger_1_4.obj" />
      </geometry>
    </collision>
  </link>
  <joint name="left_finger_1_4" type="revolute">
    <origin xyz="0.00713207092549761 0.0240670163656517 -0.019952609082273" rpy="0 0 0" />
    <parent link="left_finger_1_3" />
    <child link="left_finger_1_4" />
    <axis xyz="-0.65709860673833 -0.343316547183143 -0.671085068715427" />
    <limit effort="87.0" lower="0.0" upper="1.5708" velocity="2.0" />
  </joint>
  <link name="left_finger_2_1">
    <inertial>
      <origin xyz="0.00352481954599174 -0.000428245747455376 0.000464516138652504" rpy="0 0 0" />
      <mass value="0.0022463146140279" />
      <inertia ixx="1.86789810547945E-07" ixy="-4.89243898990565E-09" ixz="2.54116606744067E-09" iyy="1.59745221583338E-07" iyz="2.18429761495116E-09" izz="1.01375094376594E-07" />
    </inertial>
    <visual>
      <origin xyz="0 0 0" rpy="0 0 0" />
      <geometry>
        <mesh filename="../meshes/friday/visual/left_finger_2_1.obj" />
      </geometry>
    </visual>
  </link>
  <joint name="left_finger_2_1" type="revolute">
    <origin xyz="0 0.0348117061132299 -0.0874999999995938" rpy="0 0 0" />
    <parent link="left_arm_7" />
    <child link="left_finger_2_1" />
    <axis xyz="-1 0 0" />
    <limit effort="87.0" lower="-0.261" upper="0.261" velocity="2.0" />
  </joint>
  <link name="left_finger_2_2">
    <inertial>
      <origin xyz="-0.00320616542093335 0.00140147618715987 -0.0201141316654379" rpy="0 0 0" />
      <mass value="0.00955773337389186" />
      <inertia ixx="1.61087318656078E-06" ixy="-1.9733269743287E-09" ixz="7.3587250927292E-09" iyy="1.45620339017698E-06" iyz="8.57161880818813E-08" izz="3.46492890494582E-07" />
    </inertial>
    <visual>
      <origin xyz="0 0 0" rpy="0 0 0" />
      <geometry>
        <mesh filename="../meshes/friday/visual/left_finger_2_2.obj" />
      </geometry>
    </visual>
    <collision>
      <origin xyz="0 0 0" rpy="0 0 0" />
      <geometry>
        <mesh filename="../meshes/friday/collision/compact_left_finger_2_2.obj" />
      </geometry>
    </collision>
  </link>
  <joint name="left_finger_2_2" type="revolute">
    <origin xyz="0.0100999999999972 0.000662686500560963 -0.0094768584773518" rpy="0 0 0" />
    <parent link="left_finger_2_1" />
    <child link="left_finger_2_2" />
    <axis xyz="0 -0.997564050259825 -0.0697564737441203" />
    <limit effort="87.0" lower="0.0" upper="1.5708" velocity="2.0" />
  </joint>
  <link name="left_finger_2_3">
    <inertial>
      <origin xyz="-0.00333169155013013 -0.00531515059454206 -0.0135191353972155" rpy="0 0 0" />
      <mass value="0.00551060280615772" />
      <inertia ixx="5.11360971286334E-07" ixy="4.12638171945166E-10" ixz="2.11723203582247E-10" iyy="4.50134797779895E-07" iyz="6.02852093132093E-09" izz="1.83121472831875E-07" />
    </inertial>
    <visual>
      <origin xyz="0 0 0" rpy="0 0 0" />
      <geometry>
        <mesh filename="../meshes/friday/visual/left_finger_2_3.obj" />
      </geometry>
    </visual>
    <collision>
      <origin xyz="0 0 0" rpy="0 0 0" />
      <geometry>
        <mesh filename="../meshes/friday/collision/compact_left_finger_2_3.obj" />
      </geometry>
    </collision>
  </link>
  <joint name="left_finger_2_3" type="revolute">
    <origin xyz="0 0.00945190272107127 -0.0434465020901463" rpy="0 0 0" />
    <parent link="left_finger_2_2" />
    <child link="left_finger_2_3" />
    <axis xyz="0 -0.997564050259825 -0.0697564737441203" />
    <limit effort="87.0" lower="0.0" upper="1.919" velocity="2.0" />
  </joint>
  <link name="left_finger_2_4">
    <inertial>
      <origin xyz="-0.00257908212424987 -0.00948076013477261 -0.0132521249802211" rpy="0 0 0" />
      <mass value="0.00563413957469572" />
      <inertia ixx="3.61994292715335E-07" ixy="2.49408362799896E-09" ixz="-3.56666975844689E-08" iyy="3.08498619141025E-07" iyz="9.68517168166099E-09" izz="1.74495229837441E-07" />
    </inertial>
    <visual>
      <origin xyz="0 0 0" rpy="0 0 0" />
      <geometry>
        <mesh filename="../meshes/friday/visual/left_finger_2_4.obj" />
      </geometry>
    </visual>
    <collision>
      <origin xyz="0 0 0" rpy="0 0 0" />
      <geometry>
        <mesh filename="../meshes/friday/collision/compact_left_finger_2_4.obj" />
      </geometry>
    </collision>
  </link>
  <joint name="left_finger_2_4" type="revolute">
    <origin xyz="0 0.00606191065687493 -0.0296493668544514" rpy="0 0 0" />
    <parent link="left_finger_2_3" />
    <child link="left_finger_2_4" />
    <axis xyz="0 -0.997564050259825 -0.0697564737441159" />
    <limit effort="87.0" lower="0.0" upper="1.5708" velocity="2.0" />
  </joint>
  <link name="left_finger_3_1">
    <inertial>
      <origin xyz="0.00352481975712515 -0.000428246013918956 0.000464516114221825" rpy="0 0 0" />
      <mass value="0.00224631422260925" />
      <inertia ixx="1.86789805542639E-07" ixy="-4.89243678980185E-09" ixz="2.54116793308436E-09" iyy="1.59745218361143E-07" iyz="2.18430481294463E-09" izz="1.01375089225405E-07" />
    </inertial>
    <visual>
      <origin xyz="0 0 0" rpy="0 0 0" />
      <geometry>
        <mesh filename="../meshes/friday/visual/left_finger_3_1.obj" />
      </geometry>
    </visual>
  </link>
  <joint name="left_finger_3_1" type="revolute">
    <origin xyz="0 0.0138117061138729 -0.0899999999997465" rpy="-0.0698131700797682 0 0" />
    <parent link="left_arm_7" />
    <child link="left_finger_3_1" />
    <axis xyz="-1 0 0" />
    <limit effort="87.0" lower="-0.261" upper="0.261" velocity="2.0" />
  </joint>
  <link name="left_finger_3_2">
    <inertial>
      <origin xyz="-0.00320616592655684 0.0142121861305183 -0.0192183204271648" rpy="0 0 0" />
      <mass value="0.00955773254903518" />
      <inertia ixx="1.61087313481898E-06" ixy="-1.97334174360588E-09" ixz="7.35876062718472E-09" iyy="1.4562033908373E-06" iyz="8.57162252123309E-08" izz="3.46492857700334E-07" />
    </inertial>
    <visual>
      <origin xyz="0 0 0" rpy="0 0 0" />
      <geometry>
        <mesh filename="../meshes/friday/visual/left_finger_3_2.obj" />
      </geometry>
    </visual>
    <collision>
      <origin xyz="0 0 0" rpy="0 0 0" />
      <geometry>
        <mesh filename="../meshes/friday/collision/compact_left_finger_3_2.obj" />
      </geometry>
    </collision>
  </link>
  <joint name="left_finger_3_2" type="revolute">
    <origin xyz="0.0100999999999961 -0.0121480244988364 -0.0103726706550344" rpy="0 0 0" />
    <parent link="left_finger_3_1" />
    <child link="left_finger_3_2" />
    <axis xyz="0 -0.997564050259825 -0.0697564737441203" />
    <limit effort="87.0" lower="0.0" upper="1.5708" velocity="2.0" />
  </joint>
  <link name="left_finger_3_3">
    <inertial>
      <origin xyz="-0.00333169227489735 0.0121123993692984 -0.0123004795532924" rpy="0 0 0" />
      <mass value="0.00551060575044349" />
      <inertia ixx="5.11361314528619E-07" ixy="4.12631607043572E-10" ixz="2.11683536837197E-10" iyy="4.50135101305973E-07" iyz="6.02847628978208E-09" izz="1.83121572884577E-07" />
    </inertial>
    <visual>
      <origin xyz="0 0 0" rpy="0 0 0" />
      <geometry>
        <mesh filename="../meshes/friday/visual/left_finger_3_3.obj" />
      </geometry>
    </visual>
    <collision>
      <origin xyz="0 0 0" rpy="0 0 0" />
      <geometry>
        <mesh filename="../meshes/friday/collision/compact_left_finger_3_3.obj" />
      </geometry>
    </collision>
  </link>
  <joint name="left_finger_3_3" type="revolute">
    <origin xyz="0 0.00483506358585944 -0.0437693429347772" rpy="0 0 0" />
    <parent link="left_finger_3_2" />
    <child link="left_finger_3_3" />
    <axis xyz="0 -0.997564050259825 -0.0697564737441203" />
    <limit effort="87.0" lower="0.0" upper="1.919" velocity="2.0" />
  </joint>
  <link name="left_finger_3_4">
    <inertial>
      <origin xyz="-0.0025790836023756 0.0108144253156739 -0.0118329374587258" rpy="0 0 0" />
      <mass value="0.00563413308215475" />
      <inertia ixx="3.61993937790202E-07" ixy="2.49407971096253E-09" ixz="-3.56666719855433E-08" iyy="3.08498324754864E-07" iyz="9.68522374732598E-09" izz="1.74495150596009E-07" />
    </inertial>
    <visual>
      <origin xyz="0 0 0" rpy="0 0 0" />
      <geometry>
        <mesh filename="../meshes/friday/visual/left_finger_3_4.obj" />
      </geometry>
    </visual>
    <collision>
      <origin xyz="0 0 0" rpy="0 0 0" />
      <geometry>
        <mesh filename="../meshes/friday/collision/compact_left_finger_3_4.obj" />
      </geometry>
    </collision>
  </link>
  <joint name="left_finger_3_4" type="revolute">
    <origin xyz="0 0.00319427677107163 -0.0298498913513182" rpy="0 0 0" />
    <parent link="left_finger_3_3" />
    <child link="left_finger_3_4" />
    <axis xyz="0 -0.997564050259825 -0.0697564737441159" />
    <limit effort="87.0" lower="0.0" upper="1.5708" velocity="2.0" />
  </joint>
  <link name="left_finger_4_1">
    <inertial>
      <origin xyz="0.00352482021200079 -0.000428246419340583 0.000464515736760762" rpy="0 0 0" />
      <mass value="0.00224631349576038" />
      <inertia ixx="1.86789784786814E-07" ixy="-4.89243200666313E-09" ixz="2.54116766663703E-09" iyy="1.59745215688606E-07" iyz="2.18430689704463E-09" izz="1.01375066519251E-07" />
    </inertial>
    <visual>
      <origin xyz="0 0 0" rpy="0 0 0" />
      <geometry>
        <mesh filename="../meshes/friday/visual/left_finger_4_1.obj" />
      </geometry>
    </visual>
  </link>
  <joint name="left_finger_4_1" type="revolute">
    <origin xyz="0 -0.0071882938856157 -0.0860000000001848" rpy="-0.139626340159547 0 0" />
    <parent link="left_arm_7" />
    <child link="left_finger_4_1" />
    <axis xyz="-1 0 0" />
    <limit effort="87.0" lower="-0.261" upper="0.261" velocity="2.0" />
  </joint>
  <link name="left_finger_4_2">
    <inertial>
      <origin xyz="-0.00320616505560209 0.0140028572483478 -0.0192329599627835" rpy="0 0 0" />
      <mass value="0.00955773229179818" />
      <inertia ixx="1.61087311317043E-06" ixy="-1.97336286957669E-09" ixz="7.35884227895281E-09" iyy="1.45620343838423E-06" iyz="8.57163131577331E-08" izz="3.46492845431132E-07" />
    </inertial>
    <visual>
      <origin xyz="0 0 0" rpy="0 0 0" />
      <geometry>
        <mesh filename="../meshes/friday/visual/left_finger_4_2.obj" />
      </geometry>
    </visual>
    <collision>
      <origin xyz="0 0 0" rpy="0 0 0" />
      <geometry>
        <mesh filename="../meshes/friday/collision/compact_left_finger_4_2.obj" />
      </geometry>
    </collision>
  </link>
  <joint name="left_finger_4_2" type="revolute">
    <origin xyz="0.0100999999999973 -0.011938697394281 -0.0103580330794463" rpy="0 0 0" />
    <parent link="left_finger_4_1" />
    <child link="left_finger_4_2" />
    <axis xyz="0 -0.997564050259824 -0.0697564737441242" />
    <limit effort="87.0" lower="0.0" upper="1.5708" velocity="2.0" />
  </joint>
  <link name="left_finger_4_3">
    <inertial>
      <origin xyz="-0.00333169235106481 0.01302614245133 -0.0122365846859577" rpy="0 0 0" />
      <mass value="0.00551060363921408" />
      <inertia ixx="5.11361199627918E-07" ixy="4.12630142167099E-10" ixz="2.11712162660257E-10" iyy="4.50134954227979E-07" iyz="6.02848092101247E-09" izz="1.83121454288897E-07" />
    </inertial>
    <visual>
      <origin xyz="0 0 0" rpy="0 0 0" />
      <geometry>
        <mesh filename="../meshes/friday/visual/left_finger_4_3.obj" />
      </geometry>
    </visual>
    <collision>
      <origin xyz="0 0 0" rpy="0 0 0" />
      <geometry>
        <mesh filename="../meshes/friday/collision/compact_left_finger_4_3.obj" />
      </geometry>
    </collision>
  </link>
  <joint name="left_finger_4_3" type="revolute">
    <origin xyz="0 0.00371199384179977 -0.0438478756202612" rpy="0 0 0" />
    <parent link="left_finger_4_2" />
    <child link="left_finger_4_3" />
    <axis xyz="0 -0.997564050259824 -0.0697564737441242" />
    <limit effort="87.0" lower="0.0" upper="1.919" velocity="2.0" />
  </joint>
  <link name="left_finger_4_4">
    <inertial>
      <origin xyz="-0.00257908202189147 0.0106411727888073 -0.0118450612473692" rpy="0 0 0" />
      <mass value="0.00563413842087626" />
      <inertia ixx="3.61994255557094E-07" ixy="2.4940851701165E-09" ixz="-3.56666952363866E-08" iyy="3.08498581043708E-07" iyz="9.68516095892198E-09" izz="1.74495218034829E-07" />
    </inertial>
    <visual>
      <origin xyz="0 0 0" rpy="0 0 0" />
      <geometry>
        <mesh filename="../meshes/friday/visual/left_finger_4_4.obj" />
      </geometry>
    </visual>
    <collision>
      <origin xyz="0 0 0" rpy="0 0 0" />
      <geometry>
        <mesh filename="../meshes/friday/collision/compact_left_finger_4_4.obj" />
      </geometry>
    </collision>
  </link>
  <joint name="left_finger_4_4" type="revolute">
    <origin xyz="0 0.00428127089846558 -0.0297738813174416" rpy="0 0 0" />
    <parent link="left_finger_4_3" />
    <child link="left_finger_4_4" />
    <axis xyz="0 -0.997564050259824 -0.069756473744122" />
    <limit effort="87.0" lower="0.0" upper="1.5708" velocity="2.0" />
  </joint>
  <link name="left_finger_5_1">
    <inertial>
      <origin xyz="0.00352482069355836 -0.000428246772553265 0.000464515341960681" rpy="0 0 0" />
      <mass value="0.002246312738658" />
      <inertia ixx="1.86789762190528E-07" ixy="-4.89242677714828E-09" ixz="2.5411670365728E-09" iyy="1.59745213533017E-07" iyz="2.18430742206117E-09" izz="1.01375041464609E-07" />
    </inertial>
    <visual>
      <origin xyz="0 0 0" rpy="0 0 0" />
      <geometry>
        <mesh filename="../meshes/friday/visual/left_finger_5_1.obj" />
      </geometry>
    </visual>
  </link>
  <joint name="left_finger_5_1" type="revolute">
    <origin xyz="0 -0.0281882938851598 -0.0820000000009105" rpy="-0.209439510239313 0 0" />
    <parent link="left_arm_7" />
    <child link="left_finger_5_1" />
    <axis xyz="-1 0 0" />
    <limit effort="87.0" lower="-0.261" upper="0.261" velocity="2.0" />
  </joint>
  <link name="left_finger_5_2">
    <inertial>
      <origin xyz="-0.00320616455488054 0.0135882775641591 -0.0192619498045331" rpy="0 0 0" />
      <mass value="0.00955773279794779" />
      <inertia ixx="1.610873140969E-06" ixy="-1.97337128570371E-09" ixz="7.35882913042446E-09" iyy="1.45620342302151E-06" iyz="8.57163168331151E-08" izz="3.4649287515688E-07" />
    </inertial>
    <visual>
      <origin xyz="0 0 0" rpy="0 0 0" />
      <geometry>
        <mesh filename="../meshes/friday/visual/left_finger_5_2.obj" />
      </geometry>
    </visual>
    <collision>
      <origin xyz="0 0 0" rpy="0 0 0" />
      <geometry>
        <mesh filename="../meshes/friday/collision/compact_left_finger_5_2.obj" />
      </geometry>
    </collision>
  </link>
  <joint name="left_finger_5_2" type="revolute">
    <origin xyz="0.0100999999999964 -0.0115241174986501 -0.0103290428305695" rpy="0 0 0" />
    <parent link="left_finger_5_1" />
    <child link="left_finger_5_2" />
    <axis xyz="0 -0.997564050259825 -0.0697564737441178" />
    <limit effort="87.0" lower="0.0" upper="1.5708" velocity="2.0" />
  </joint>
  <link name="left_finger_5_3">
    <inertial>
      <origin xyz="-0.00333168954672705 0.0115627991641559 -0.0123389262356737" rpy="0 0 0" />
      <mass value="0.00551059780137605" />
      <inertia ixx="5.11359970911288E-07" ixy="4.12629538947359E-10" ixz="2.11630792618058E-10" iyy="4.50134105201727E-07" iyz="6.02797436695343E-09" izz="1.83121213416435E-07" />
    </inertial>
    <visual>
      <origin xyz="0 0 0" rpy="0 0 0" />
      <geometry>
        <mesh filename="../meshes/friday/visual/left_finger_5_3.obj" />
      </geometry>
    </visual>
    <collision>
      <origin xyz="0 0 0" rpy="0 0 0" />
      <geometry>
        <mesh filename="../meshes/friday/collision/compact_left_finger_5_3.obj" />
      </geometry>
    </collision>
  </link>
  <joint name="left_finger_5_3" type="revolute">
    <origin xyz="0 0.00476076360242195 -0.0437745384944359" rpy="0 0 0" />
    <parent link="left_finger_5_2" />
    <child link="left_finger_5_3" />
    <axis xyz="0 -0.997564050259825 -0.0697564737441156" />
    <limit effort="87.0" lower="0.0" upper="1.919" velocity="2.0" />
  </joint>
  <link name="left_finger_5_4">
    <inertial>
      <origin xyz="-0.00257908192778722 0.0102980421183413 -0.0118690557649419" rpy="0 0 0" />
      <mass value="0.0056341384823792" />
      <inertia ixx="3.61994295774377E-07" ixy="2.49408678376138E-09" ixz="-3.56666987767493E-08" iyy="3.08498614843608E-07" iyz="9.68515483852365E-09" izz="1.74495218146791E-07" />
    </inertial>
    <visual>
      <origin xyz="0 0 0" rpy="0 0 0" />
      <geometry>
        <mesh filename="../meshes/friday/visual/left_finger_5_4.obj" />
      </geometry>
    </visual>
    <collision>
      <origin xyz="0 0 0" rpy="0 0 0" />
      <geometry>
        <mesh filename="../meshes/friday/collision/compact_left_finger_5_4.obj" />
      </geometry>
    </collision>
  </link>
  <joint name="left_finger_5_4" type="revolute">
    <origin xyz="0 0.00306129565376206 -0.0298591902970081" rpy="0 0 0" />
    <parent link="left_finger_5_3" />
    <child link="left_finger_5_4" />
    <axis xyz="0 -0.997564050259825 -0.0697564737441156" />
    <limit effort="87.0" lower="0.0" upper="1.5708" velocity="2.0" />
  </joint>

  <link name="right_arm_1">
    <inertial>
      <origin xyz="-0.0504783902306926 0.00890129178533927 -0.00679453644214538" rpy="0 0 0" />
      <mass value="0.651474546540579" />
      <inertia ixx="0.000731842888672747" ixy="3.59742635586591E-05" ixz="-3.81367597786363E-05" iyy="0.000929468035003683" iyz="6.73422556956025E-06" izz="0.000892686460138007" />
    </inertial>
    <visual>
      <origin xyz="0 0 0" rpy="0 0 0" />
      <geometry>
        <mesh filename="../meshes/friday/visual/right_arm_1.obj" />
      </geometry>
    </visual>
  </link>
  <joint name="right_arm_1" type="revolute">
    <!-- <origin xyz="-0.162181324471144 0.229426591735731 0" rpy="0 0 0" /> -->
    <origin xyz="-0.172029404471144 0.231163071735731 0" rpy="0 0 0" />
    <parent link="waist_5" />
    <child link="right_arm_1" />
    <axis xyz="-0.984807753012208 0.173648177666932 0" />
    <limit effort="87.0" lower="-0.4236" upper="2.5180" velocity="2.0" />
  </joint>
  <link name="right_arm_2">
    <inertial>
      <origin xyz="-0.00876610551709145 -0.0838925972250821 -0.000116637744680237" rpy="0 0 0" />
      <mass value="0.552803787561506" />
      <inertia ixx="0.000519188555883051" ixy="-8.90912453909685E-06" ixz="1.5759114172996E-06" iyy="0.000459209519989159" iyz="8.14107358177029E-06" izz="0.000544537600281593" />
    </inertial>
    <visual>
      <origin xyz="0 0 0" rpy="0 0 0" />
      <geometry>
        <mesh filename="../meshes/friday/visual/right_arm_2.obj" />
      </geometry>
    </visual>
    <collision>
      <origin xyz="0 0 0" rpy="0 0 0" />
      <geometry>
        <mesh filename="../meshes/friday/collision/compact_right_arm_2.obj" />
      </geometry>
    </collision>
  </link>
  <joint name="right_arm_2" type="revolute">
    <origin xyz="-0.0590971787351876 0.0104204270947499 0" rpy="0 0 0" />
    <parent link="right_arm_1" />
    <child link="right_arm_2" />
    <axis xyz="0 0 -1" />
    <limit effort="87.0" lower="0.0" upper="2.2562" velocity="2.0" />
  </joint>
  <link name="right_arm_3">
    <inertial>
      <origin xyz="-0.000133731452946151 -0.0679041256616604 -0.0020044978911568" rpy="0 0 0" />
      <mass value="0.726149922961283" />
      <inertia ixx="0.00135809777973873" ixy="-5.89216930081264E-06" ixz="1.34889818650324E-06" iyy="0.000527337663742348" iyz="-3.44595442111269E-05" izz="0.00136476731130073" />
    </inertial>
    <visual>
      <origin xyz="0 0 0" rpy="0 0 0" />
      <geometry>
        <mesh filename="../meshes/friday/visual/right_arm_3.obj" />
      </geometry>
    </visual>
    <collision>
      <origin xyz="0 -0.1 0.0" rpy="0 0 0" />
      <geometry>
				<box size="0.065 0.08 0.06" />
			</geometry>
    </collision>
  </link>
  <joint name="right_arm_3" type="revolute">
    <origin xyz="-0.0100000000000191 -0.136500000000018 0" rpy="0 0 0" />
    <parent link="right_arm_2" />
    <child link="right_arm_3" />
    <axis xyz="0 -1 0" />
    <limit effort="87.0" lower="-1.4708" upper="1.4708" velocity="2.0" />
  </joint>
  <link name="right_arm_4">
    <inertial>
      <origin xyz="-2.76445533131664E-14 -0.045952576906095 -0.0136740346459322" rpy="0 0 0" />
      <mass value="0.467228469256572" />
      <inertia ixx="0.000771988372959408" ixy="1.94600978543822E-16" ixz="4.31013975029117E-12" iyy="0.000278940153191588" iyz="4.81484159713596E-06" izz="0.000775309371405241" />
    </inertial>
    <visual>
      <origin xyz="0 0 0" rpy="0 0 0" />
      <geometry>
        <mesh filename="../meshes/friday/visual/right_arm_4.obj" />
      </geometry>
    </visual>
    <collision>
      <origin xyz="0 0 0" rpy="0 0 0" />
      <geometry>
        <mesh filename="../meshes/friday/collision/compact_right_arm_4.obj" />
      </geometry>
    </collision>
  </link>
  <joint name="right_arm_4" type="revolute">
    <origin xyz="0 -0.13 0.0134999999984212" rpy="0 0 0" />
    <parent link="right_arm_3" />
    <child link="right_arm_4" />
    <axis xyz="-1 0 0" />
    <limit effort="87.0" lower="0.0" upper="2.1689" velocity="2.0" />
  </joint>
  <link name="right_arm_5">
    <inertial>
      <origin xyz="5.77929130494981E-05 -2.10908799249993E-05 0.0303745916076382" rpy="0 0 0" />
      <mass value="0.141645120498882" />
      <inertia ixx="0.000150674876586753" ixy="-9.98797795815426E-06" ixz="-9.93466915122478E-08" iyy="0.00015148916187729" iyz="8.09491309586898E-08" izz="7.93773197761316E-05" />
    </inertial>
    <visual>
      <origin xyz="0 0 0" rpy="0 0 0" />
      <geometry>
        <mesh filename="../meshes/friday/visual/right_arm_5.obj" />
      </geometry>
    </visual>
    <collision>
      <origin xyz="0 0 0" rpy="0 0 0" />
      <geometry>
        <mesh filename="../meshes/friday/collision/compact_right_arm_5.obj" />
      </geometry>
    </collision>
  </link>
  <joint name="right_arm_5" type="revolute">
    <origin xyz="0 -0.10259999999999 -0.0134999999984212" rpy="1.5707963267949 0 0" />
    <parent link="right_arm_4" />
    <child link="right_arm_5" />
    <axis xyz="0 0 1" />
    <limit effort="87.0" lower="-1.4708" upper="1.4708" velocity="2.0" />
  </joint>
  <link name="right_arm_6">
    <inertial>
      <origin xyz="-8.14545597892236E-05 7.51009215400755E-05 0.0117608666205656" rpy="0 0 0" />
      <mass value="0.0314621801352106" />
      <inertia ixx="7.82929735327741E-06" ixy="1.10612506401232E-08" ixz="1.46345904053749E-08" iyy="8.71321796162152E-06" iyz="-7.15856215621043E-09" izz="7.73497403513718E-06" />
    </inertial>
    <visual>
      <origin xyz="0 0 0" rpy="0 0 0" />
      <geometry>
        <mesh filename="../meshes/friday/visual/right_arm_6.obj" />
      </geometry>
    </visual>
  </link>
  <joint name="right_arm_6" type="revolute">
    <origin xyz="0 0 0.111999999999983" rpy="0 0 0" />
    <parent link="right_arm_5" />
    <child link="right_arm_6" />
    <axis xyz="0 -1 0" />
    <limit effort="87.0" lower="-0.9472" upper="0.9472" velocity="2.0" />
  </joint>
  <link name="right_arm_7">
    <inertial>
      <origin xyz="0.00155644949116443 0.00311722917436926 0.0509010500036021" rpy="0 0 0" />
      <mass value="0.131756699270941" />
      <inertia ixx="7.77647231616779E-05" ixy="-8.79445374853935E-07" ixz="8.86916310181377E-07" iyy="3.25934806046904E-05" iyz="-6.93098580275756E-06" izz="5.59120417690713E-05" />
    </inertial>
    <visual>
      <origin xyz="0 0 0" rpy="0 0 0" />
      <geometry>
        <mesh filename="../meshes/friday/visual/right_arm_7.obj" />
      </geometry>
    </visual>
    <collision>
      <origin xyz="0 0 0" rpy="0 0 0" />
      <geometry>
        <mesh filename="../meshes/friday/collision/compact_right_arm_7.obj" />
      </geometry>
    </collision>
  </link>
  <joint name="right_arm_7" type="revolute">
    <origin xyz="0 0 0.0400000000000003" rpy="0 0 0" />
    <parent link="right_arm_6" />
    <child link="right_arm_7" />
    <axis xyz="-1 0 0" />
    <limit effort="87.0" lower="-0.6854" upper="0.6854" velocity="2.0" />
  </joint>
  <link name="right_finger_1_1">
    <inertial>
      <origin xyz="0.00392419816759348 0.0136427135614177 0.00414363284733754" rpy="0 0 0" />
      <mass value="0.00772717117271342" />
      <inertia ixx="1.10265527557138E-06" ixy="-8.47564377055795E-08" ixz="9.2298864528611E-09" iyy="6.86434027236117E-07" iyz="-2.33633518885702E-07" izz="5.92242883867801E-07" />
    </inertial>
    <visual>
      <origin xyz="0 0 0" rpy="0 0 0" />
      <geometry>
        <mesh filename="../meshes/friday/visual/right_finger_1_1.obj" />
      </geometry>
    </visual>
    <collision>
      <origin xyz="0 0 0" rpy="0 0 0" />
      <geometry>
        <mesh filename="../meshes/friday/collision/compact_right_finger_1_1.obj" />
      </geometry>
    </collision>
  </link>
  <joint name="right_finger_1_1" type="revolute">
    <origin xyz="0.0130000000000003 0.0315772628474916 0.0477824821133407" rpy="0 0 0" />
    <parent link="right_arm_7" />
    <child link="right_finger_1_1" />
    <axis xyz="0 -0.374606593415932 -0.927183854566779" />
    <limit effort="87.0" lower="-3.142" upper="3.142" velocity="2.0" />
  </joint>
  <link name="right_finger_1_2">
    <inertial>
      <origin xyz="0.00193519430262745 0.00296052560510073 -0.00850415168602969" rpy="0 0 0" />
      <mass value="0.00174088151204446" />
      <inertia ixx="1.48560600308852E-07" ixy="-9.36029109432097E-09" ixz="-1.21227876281998E-08" iyy="1.23941566698946E-07" iyz="-4.17646268475841E-08" izz="6.90664111795504E-08" />
    </inertial>
    <visual>
      <origin xyz="0 0 0" rpy="0 0 0" />
      <geometry>
        <mesh filename="../meshes/friday/visual/right_finger_1_2.obj" />
      </geometry>
    </visual>
  </link>
  <joint name="right_finger_1_2" type="revolute">
    <origin xyz="0.00255010042326079 0.0286948142815985 0.0171767671995365" rpy="0 0 0" />
    <parent link="right_finger_1_1" />
    <child link="right_finger_1_2" />
    <axis xyz="0.657098606720061 0.343316547193198 -0.671085068728172" />
    <limit effort="87.0" lower="-3.142" upper="3.142" velocity="2.0" />
  </joint>
  <link name="right_finger_1_3">
    <inertial>
      <origin xyz="0.00209451481474418 0.012572527670925 0.0080167887872219" rpy="0 0 0" />
      <mass value="0.00668483267289781" />
      <inertia ixx="5.9054971507277E-07" ixy="-6.08102128928416E-08" ixz="2.42698791134905E-08" iyy="4.02059841255816E-07" iyz="-1.49275159455177E-07" izz="4.75031864036228E-07" />
    </inertial>
    <visual>
      <origin xyz="0 0 0" rpy="0 0 0" />
      <geometry>
        <mesh filename="../meshes/friday/visual/right_finger_1_3.obj" />
      </geometry>
    </visual>
    <collision>
      <origin xyz="0 0 0" rpy="0 0 0" />
      <geometry>
        <mesh filename="../meshes/friday/collision/compact_right_finger_1_3.obj" />
      </geometry>
    </collision>
  </link>
  <joint name="right_finger_1_3" type="revolute">
    <origin xyz="0.00483379709378198 0.00874788690819759 0.00204842295524477" rpy="0 0 0" />
    <parent link="right_finger_1_2" />
    <child link="right_finger_1_3" />
    <axis xyz="0.730425975910616 -0.509989436084484 0.4543001967832" />
    <limit effort="87.0" lower="-3.142" upper="3.142" velocity="2.0" />
  </joint>
  <link name="right_finger_1_4">
    <inertial>
      <origin xyz="0.00131199003016585 0.0135338692083564 0.00616552231422474" rpy="0 0 0" />
      <mass value="0.00756254861820415" />
      <inertia ixx="6.551370392926E-07" ixy="-5.94366726400603E-08" ixz="3.4559147875081E-08" iyy="3.7632025445703E-07" iyz="-1.66799101672845E-07" izz="5.37284949409765E-07" />
    </inertial>
    <visual>
      <origin xyz="0 0 0" rpy="0 0 0" />
      <geometry>
        <mesh filename="../meshes/friday/visual/right_finger_1_4.obj" />
      </geometry>
    </visual>
    <collision>
      <origin xyz="0 0 0" rpy="0 0 0" />
      <geometry>
        <mesh filename="../meshes/friday/collision/compact_right_finger_1_4.obj" />
      </geometry>
    </collision>
  </link>
  <joint name="right_finger_1_4" type="revolute">
    <origin xyz="0.00652036145977081 0.0237474144313334 0.0205773389004803" rpy="0 0 0" />
    <parent link="right_finger_1_3" />
    <child link="right_finger_1_4" />
    <axis xyz="0.657098606720065 0.343316547193201 -0.671085068728166" />
    <limit effort="87.0" lower="-3.142" upper="3.142" velocity="2.0" />
  </joint>
  <link name="right_finger_2_1">
    <inertial>
      <origin xyz="0.00342483400632929 -0.00042827101108233 -0.000464517809992682" rpy="0 0 0" />
      <mass value="0.00224629763705336" />
      <inertia ixx="1.86788698004925E-07" ixy="-4.89238008397515E-09" ixz="-2.54124369204958E-09" iyy="1.59744965939733E-07" iyz="-2.18459416155055E-09" izz="1.01374052827499E-07" />
    </inertial>
    <visual>
      <origin xyz="0 0 0" rpy="0 0 0" />
      <geometry>
        <mesh filename="../meshes/friday/visual/right_finger_2_1.obj" />
      </geometry>
    </visual>
  </link>
  <joint name="right_finger_2_1" type="revolute">
    <origin xyz="0 0.0348117061119276 0.0875000000000032" rpy="0 0 0" />
    <parent link="right_arm_7" />
    <child link="right_finger_2_1" />
    <axis xyz="1 0 0" />
    <limit effort="87.0" lower="-3.142" upper="3.142" velocity="2.0" />
  </joint>
  <link name="right_finger_2_2">
    <inertial>
      <origin xyz="-0.00320616302054577 -0.0111718011869911 0.0209933408637044" rpy="0 0 0" />
      <mass value="0.00955766794847846" />
      <inertia ixx="1.61085720086254E-06" ixy="-1.9730064060257E-09" ixz="-7.35842493669712E-09" iyy="1.45618882725641E-06" iyz="-8.57141628231748E-08" izz="3.46488365188027E-07" />
    </inertial>
    <visual>
      <origin xyz="0 0 0" rpy="0 0 0" />
      <geometry>
        <mesh filename="../meshes/friday/visual/right_finger_2_2.obj" />
      </geometry>
    </visual>
    <collision>
      <origin xyz="0 0 0" rpy="0 0 0" />
      <geometry>
        <mesh filename="../meshes/friday/collision/compact_right_finger_2_2.obj" />
      </geometry>
    </collision>
  </link>
  <joint name="right_finger_2_2" type="revolute">
    <origin xyz="0.00999999999999807 0.0132359248950032 0.00859765200073959" rpy="0 0 0" />
    <parent link="right_finger_2_1" />
    <child link="right_finger_2_2" />
    <axis xyz="0 0.997564050259825 -0.0697564737441203" />
    <limit effort="87.0" lower="-3.142" upper="3.142" velocity="2.0" />
  </joint>
  <link name="right_finger_2_3">
    <inertial>
      <origin xyz="-0.00333151873291382 -0.00888389277933833 0.0137684081407743" rpy="0 0 0" />
      <mass value="0.00551056847509123" />
      <inertia ixx="5.11342723009075E-07" ixy="4.12475911870065E-10" ixz="-2.13864214584013E-10" iyy="4.50118444047335E-07" iyz="-6.02685186746674E-09" izz="1.83121549265943E-07" />
    </inertial>
    <visual>
      <origin xyz="0 0 0" rpy="0 0 0" />
      <geometry>
        <mesh filename="../meshes/friday/visual/right_finger_2_3.obj" />
      </geometry>
    </visual>
    <collision>
      <origin xyz="0 0 0" rpy="0 0 0" />
      <geometry>
        <mesh filename="../meshes/friday/collision/compact_right_finger_2_3.obj" />
      </geometry>
    </collision>
  </link>
  <joint name="right_finger_2_3" type="revolute">
    <origin xyz="0 0.000447386794015091 0.0440761591833604" rpy="0 0 0" />
    <parent link="right_finger_2_2" />
    <child link="right_finger_2_3" />
    <axis xyz="0 0.997564050259825 -0.0697564737441203" />
    <limit effort="87.0" lower="-3.142" upper="3.142" velocity="2.0" />
  </joint>
  <link name="right_finger_2_4">
    <inertial>
      <origin xyz="-0.00257925852719368 -0.00947979339681777 0.0132510851533736" rpy="0 0 0" />
      <mass value="0.00563351689092957" />
      <inertia ixx="3.61947232946021E-07" ixy="2.49745342881266E-09" ixz="3.56643136251718E-08" iyy="3.08470817611911E-07" iyz="-9.71963560117894E-09" izz="1.744760221178E-07" />
    </inertial>
    <visual>
      <origin xyz="0 0 0" rpy="0 0 0" />
      <geometry>
        <mesh filename="../meshes/friday/visual/right_finger_2_4.obj" />
      </geometry>
    </visual>
    <collision>
      <origin xyz="0 0 0" rpy="0 0 0" />
      <geometry>
        <mesh filename="../meshes/friday/collision/compact_right_finger_2_4.obj" />
      </geometry>
    </collision>
  </link>
  <joint name="right_finger_2_4" type="revolute">
    <origin xyz="0 0.00249318818092235 0.0298989162413679" rpy="0 0 0" />
    <parent link="right_finger_2_3" />
    <child link="right_finger_2_4" />
    <axis xyz="0 0.997564050259825 -0.0697564737441203" />
    <limit effort="87.0" lower="-3.142" upper="3.142" velocity="2.0" />
  </joint>
  <link name="right_finger_3_1">
    <inertial>
      <origin xyz="0.00342483415624312 -0.000428272867616278 -0.000464516599601672" rpy="0 0 0" />
      <mass value="0.00224629679090595" />
      <inertia ixx="1.86788683426246E-07" ixy="-4.89238431400507E-09" ixz="-2.54123818707286E-09" iyy="1.59744968726412E-07" iyz="-2.18460055078134E-09" izz="1.01374036740885E-07" />
    </inertial>
    <visual>
      <origin xyz="0 0 0" rpy="0 0 0" />
      <geometry>
        <mesh filename="../meshes/friday/visual/right_finger_3_1.obj" />
      </geometry>
    </visual>
  </link>
  <joint name="right_finger_3_1" type="revolute">
    <origin xyz="0 0.0138117061119282 0.0900000000000032" rpy="0.0698131700797682 0 0" />
    <parent link="right_arm_7" />
    <child link="right_finger_3_1" />
    <axis xyz="1 0 0" />
    <limit effort="87.0" lower="-3.142" upper="3.142" velocity="2.0" />
  </joint>
  <link name="right_finger_3_2">
    <inertial>
      <origin xyz="-0.00320616320893288 -0.0111718022048606 0.0209933417126286" rpy="0 0 0" />
      <mass value="0.00955766759109387" />
      <inertia ixx="1.61085724698961E-06" ixy="-1.97303302524863E-09" ixz="-7.3584476491283E-09" iyy="1.45618893897801E-06" iyz="-8.5714222211329E-08" izz="3.46488338360485E-07" />
    </inertial>
    <visual>
      <origin xyz="0 0 0" rpy="0 0 0" />
      <geometry>
        <mesh filename="../meshes/friday/visual/right_finger_3_2.obj" />
      </geometry>
    </visual>
    <collision>
      <origin xyz="0 0 0" rpy="0 0 0" />
      <geometry>
        <mesh filename="../meshes/friday/collision/compact_right_finger_3_2.obj" />
      </geometry>
    </collision>
  </link>
  <joint name="right_finger_3_2" type="revolute">
    <origin xyz="0.00999999999999807 0.0132359248950032 0.00859765200073981" rpy="0 0 0" />
    <parent link="right_finger_3_1" />
    <child link="right_finger_3_2" />
    <axis xyz="0 0.997564050259824 -0.0697564737441203" />
    <limit effort="87.0" lower="-3.142" upper="3.142" velocity="2.0" />
  </joint>
  <link name="right_finger_3_3">
    <inertial>
      <origin xyz="-0.00333151899217213 -0.00888389334390426 0.0137684073891541" rpy="0 0 0" />
      <mass value="0.00551056789208471" />
      <inertia ixx="5.11342674798444E-07" ixy="4.12453037244699E-10" ixz="-2.13892059526317E-10" iyy="4.5011835582935E-07" iyz="-6.02681328032683E-09" izz="1.83121506107412E-07" />
    </inertial>
    <visual>
      <origin xyz="0 0 0" rpy="0 0 0" />
      <geometry>
        <mesh filename="../meshes/friday/visual/right_finger_3_3.obj" />
      </geometry>
    </visual>
    <collision>
      <origin xyz="0 0 0" rpy="0 0 0" />
      <geometry>
        <mesh filename="../meshes/friday/collision/compact_right_finger_3_3.obj" />
      </geometry>
    </collision>
  </link>
  <joint name="right_finger_3_3" type="revolute">
    <origin xyz="0 0.000447386794015001 0.0440761591833604" rpy="0 0 0" />
    <parent link="right_finger_3_2" />
    <child link="right_finger_3_3" />
    <axis xyz="0 0.997564050259825 -0.069756473744118" />
    <limit effort="87.0" lower="-3.142" upper="3.142" velocity="2.0" />
  </joint>
  <link name="right_finger_3_4">
    <inertial>
      <origin xyz="-0.00257925861686281 -0.00947979338130717 0.0132510849567083" rpy="0 0 0" />
      <mass value="0.00563351709625984" />
      <inertia ixx="3.61947224680467E-07" ixy="2.49745653310491E-09" ixz="3.56643100792407E-08" iyy="3.08470812232884E-07" iyz="-9.71962635634973E-09" izz="1.74476027167751E-07" />
    </inertial>
    <visual>
      <origin xyz="0 0 0" rpy="0 0 0" />
      <geometry>
        <mesh filename="../meshes/friday/visual/right_finger_3_4.obj" />
      </geometry>
    </visual>
    <collision>
      <origin xyz="0 0 0" rpy="0 0 0" />
      <geometry>
        <mesh filename="../meshes/friday/collision/compact_right_finger_3_4.obj" />
      </geometry>
    </collision>
  </link>
  <joint name="right_finger_3_4" type="revolute">
    <origin xyz="0 0.0024931881809224 0.029898916241368" rpy="0 0 0" />
    <parent link="right_finger_3_3" />
    <child link="right_finger_3_4" />
    <axis xyz="0 0.997564050259825 -0.0697564737441181" />
    <limit effort="87.0" lower="-3.142" upper="3.142" velocity="2.0" />
  </joint>
  <link name="right_finger_4_1">
    <inertial>
      <origin xyz="0.0034248343866746 -0.000428274863902692 -0.000464515884046834" rpy="0 0 0" />
      <mass value="0.00224629586557561" />
      <inertia ixx="1.8678866001828E-07" ixy="-4.89238813316046E-09" ixz="-2.54123420645512E-09" iyy="1.59744973345081E-07" iyz="-2.1845995217564E-09" izz="1.01374010539952E-07" />
    </inertial>
    <visual>
      <origin xyz="0 0 0" rpy="0 0 0" />
      <geometry>
        <mesh filename="../meshes/friday/visual/right_finger_4_1.obj" />
      </geometry>
    </visual>
  </link>
  <joint name="right_finger_4_1" type="revolute">
    <origin xyz="0 -0.00718829388807178 0.0860000000000032" rpy="0.139626340159547 0 0" />
    <parent link="right_arm_7" />
    <child link="right_finger_4_1" />
    <axis xyz="1 0 0" />
    <limit effort="87.0" lower="-3.142" upper="3.142" velocity="2.0" />
  </joint>
  <link name="right_finger_4_2">
    <inertial>
      <origin xyz="-0.00320616230611476 -0.0109625197773792 0.0209787088935511" rpy="0 0 0" />
      <mass value="0.00955766844505906" />
      <inertia ixx="1.61085741091381E-06" ixy="-1.97307047541062E-09" ixz="-7.3585303556739E-09" iyy="1.45618918981583E-06" iyz="-8.57143751934159E-08" izz="3.46488330480801E-07" />
    </inertial>
    <visual>
      <origin xyz="0 0 0" rpy="0 0 0" />
      <geometry>
        <mesh filename="../meshes/friday/visual/right_finger_4_2.obj" />
      </geometry>
    </visual>
    <collision>
      <origin xyz="0 0 0" rpy="0 0 0" />
      <geometry>
        <mesh filename="../meshes/friday/collision/compact_right_finger_4_2.obj" />
      </geometry>
    </collision>
  </link>
  <joint name="right_finger_4_2" type="revolute">
    <origin xyz="0.00999999999999812 0.013026640630767 0.00861228658212754" rpy="0 0 0" />
    <parent link="right_finger_4_1" />
    <child link="right_finger_4_2" />
    <axis xyz="0 0.997564050259824 -0.0697564737441264" />
    <limit effort="87.0" lower="-3.142" upper="3.142" velocity="2.0" />
  </joint>
  <link name="right_finger_4_3">
    <inertial>
      <origin xyz="-0.00333151918264354 -0.00520957173748776 0.0135114745666423" rpy="0 0 0" />
      <mass value="0.00551056775751513" />
      <inertia ixx="5.1134270640926E-07" ixy="4.12451296086811E-10" ixz="-2.13859192636507E-10" iyy="4.50118372033412E-07" iyz="-6.02676364935143E-09" izz="1.83121499736479E-07" />
    </inertial>
    <visual>
      <origin xyz="0 0 0" rpy="0 0 0" />
      <geometry>
        <mesh filename="../meshes/friday/visual/right_finger_4_3.obj" />
      </geometry>
    </visual>
    <collision>
      <origin xyz="0 0 0" rpy="0 0 0" />
      <geometry>
        <mesh filename="../meshes/friday/collision/compact_right_finger_4_3.obj" />
      </geometry>
    </collision>
  </link>
  <joint name="right_finger_4_3" type="revolute">
    <origin xyz="0 -0.00301765100665219 0.0443184582300248" rpy="0 0 0" />
    <parent link="right_finger_4_2" />
    <child link="right_finger_4_3" />
    <axis xyz="0 0.997564050259824 -0.0697564737441264" />
    <limit effort="87.0" lower="-3.142" upper="3.142" velocity="2.0" />
  </joint>
  <link name="right_finger_4_4">
    <inertial>
      <origin xyz="-0.00257925883414226 -0.00891729502636222 0.0132117513243505" rpy="0 0 0" />
      <mass value="0.00563351724742247" />
      <inertia ixx="3.61947233607878E-07" ixy="2.49745381383231E-09" ixz="3.56643136675739E-08" iyy="3.08470830492723E-07" iyz="-9.71961416551468E-09" izz="1.74476019391892E-07" />
    </inertial>
    <visual>
      <origin xyz="0 0 0" rpy="0 0 0" />
      <geometry>
        <mesh filename="../meshes/friday/visual/right_finger_4_4.obj" />
      </geometry>
    </visual>
    <collision>
      <origin xyz="0 0 0" rpy="0 0 0" />
      <geometry>
        <mesh filename="../meshes/friday/collision/compact_right_finger_4_4.obj" />
      </geometry>
    </collision>
  </link>
  <joint name="right_finger_4_4" type="revolute">
    <origin xyz="0 0.00560501191355511 0.0296813163284149" rpy="0 0 0" />
    <parent link="right_finger_4_3" />
    <child link="right_finger_4_4" />
    <axis xyz="0 0.997564050259824 -0.0697564737441242" />
    <limit effort="87.0" lower="-3.142" upper="3.142" velocity="2.0" />
  </joint>
  <link name="right_finger_5_1">
    <inertial>
      <origin xyz="0.00342483463070667 -0.000428276822578982 -0.000464515301615287" rpy="0 0 0" />
      <mass value="0.00224629492807521" />
      <inertia ixx="1.86788636420902E-07" ixy="-4.89239179883741E-09" ixz="-2.54123055388374E-09" iyy="1.59744978589329E-07" iyz="-2.18459664940882E-09" izz="1.01373983615964E-07" />
    </inertial>
    <visual>
      <origin xyz="0 0 0" rpy="0 0 0" />
      <geometry>
        <mesh filename="../meshes/friday/visual/right_finger_5_1.obj" />
      </geometry>
    </visual>
  </link>
  <joint name="right_finger_5_1" type="revolute">
    <origin xyz="0 -0.0281882938880725 0.0820000000000032" rpy="0.209439510239313 0 0" />
    <parent link="right_arm_7" />
    <child link="right_finger_5_1" />
    <axis xyz="1 0 0" />
    <limit effort="87.0" lower="-3.142" upper="3.142" velocity="2.0" />
  </joint>
  <link name="right_finger_5_2">
    <inertial>
      <origin xyz="-0.00320616176459509 0.00140143453408567 0.0201141366429887" rpy="0 0 0" />
      <mass value="0.00955766862031042" />
      <inertia ixx="1.61085738545546E-06" ixy="-1.97308057679324E-09" ixz="-7.35852049408318E-09" iyy="1.45618912673552E-06" iyz="-8.57143635847515E-08" izz="3.46488350090714E-07" />
    </inertial>
    <visual>
      <origin xyz="0 0 0" rpy="0 0 0" />
      <geometry>
        <mesh filename="../meshes/friday/visual/right_finger_5_2.obj" />
      </geometry>
    </visual>
    <collision>
      <origin xyz="0 0 0" rpy="0 0 0" />
      <geometry>
        <mesh filename="../meshes/friday/collision/compact_right_finger_5_2.obj" />
      </geometry>
    </collision>
  </link>
  <joint name="right_finger_5_2" type="revolute">
    <origin xyz="0.00999999999999771 0.000662686500569137 0.00947685847746849" rpy="0 0 0" />
    <parent link="right_finger_5_1" />
    <child link="right_finger_5_2" />
    <axis xyz="0 0.997564050259825 -0.0697564737441178" />
    <limit effort="87.0" lower="-3.142" upper="3.142" velocity="2.0" />
  </joint>
  <link name="right_finger_5_3">
    <inertial>
      <origin xyz="-0.00333151812882732 0.00106744828203434 0.0130725427995187" rpy="0 0 0" />
      <mass value="0.00551056915292355" />
      <inertia ixx="5.1134276181029E-07" ixy="4.12486517162502E-10" ixz="-2.13845548477208E-10" iyy="4.50118514821879E-07" iyz="-6.02688544885716E-09" izz="1.83121582856644E-07" />
    </inertial>
    <visual>
      <origin xyz="0 0 0" rpy="0 0 0" />
      <geometry>
        <mesh filename="../meshes/friday/visual/right_finger_5_3.obj" />
      </geometry>
    </visual>
    <collision>
      <origin xyz="0 0 0" rpy="0 0 0" />
      <geometry>
        <mesh filename="../meshes/friday/collision/compact_right_finger_5_3.obj" />
      </geometry>
    </collision>
  </link>
  <joint name="right_finger_5_3" type="revolute">
    <origin xyz="0 0.00306928484474117 0.043892818211432" rpy="0 0 0" />
    <parent link="right_finger_5_2" />
    <child link="right_finger_5_3" />
    <axis xyz="0 0.997564050259825 -0.0697564737441178" />
    <limit effort="87.0" lower="-3.142" upper="3.142" velocity="2.0" />
  </joint>
  <link name="right_finger_5_4">
    <inertial>
      <origin xyz="-0.00257925901237152 0.0103005974776408 0.0118679051797359" rpy="0 0 0" />
      <mass value="0.00563351738315951" />
      <inertia ixx="3.61947228520759E-07" ixy="2.49745483367572E-09" ixz="3.5664313060765E-08" iyy="3.08470832571723E-07" iyz="-9.71960588424547E-09" izz="1.74476017185668E-07" />
    </inertial>
    <visual>
      <origin xyz="0 0 0" rpy="0 0 0" />
      <geometry>
        <mesh filename="../meshes/friday/visual/right_finger_5_4.obj" />
      </geometry>
    </visual>
    <collision>
      <origin xyz="0 0 0" rpy="0 0 0" />
      <geometry>
        <mesh filename="../meshes/friday/collision/compact_right_finger_5_4.obj" />
      </geometry>
    </collision>
  </link>
  <joint name="right_finger_5_4" type="revolute">
    <origin xyz="0 -0.0073358622158608 0.030586230400047" rpy="0 0 0" />
    <parent link="right_finger_5_3" />
    <child link="right_finger_5_4" />
    <axis xyz="0 0.997564050259825 -0.0697564737441178" />
    <limit effort="87.0" lower="-3.142" upper="3.142" velocity="2.0" />
  </joint>
  <link name="head_1">
    <inertial>
      <origin xyz="-0.000292293643905175 0.0590897099738228 0.000772470872536509" rpy="0 0 0" />
      <mass value="0.735552591627434" />
      <inertia ixx="0.00141892180581131" ixy="-1.92303918045358E-05" ixz="-4.49527020854923E-07" iyy="0.00103083637893402" iyz="-2.37690039671259E-05" izz="0.00167606111322358" />
    </inertial>
    <visual>
      <origin xyz="0 0 0" rpy="0 0 0" />
      <geometry>
        <mesh filename="../meshes/friday/visual/neck.obj" />
      </geometry>
    </visual>
  </link>
  <joint name="head_1" type="revolute">
    <origin xyz="0 0.310000000000001 0" rpy="0 0 0" />
    <parent link="waist_5" />
    <child link="head_1" />
    <axis xyz="1 0 0" />
    <limit effort="87.0" lower="-0.5109" upper="0.8599" velocity="2.0" />
  </joint>
  <link name="head_2">
    <inertial>
      <origin xyz="0.000358988153587554 0.131383640357615 0.0839139789185225" rpy="0 0 0" />
      <mass value="0.354105786425473" />
      <inertia ixx="0.000932833859194997" ixy="2.6232465283442E-07" ixz="1.5968783905671E-06" iyy="0.000639876196899521" iyz="5.03156801437357E-05" izz="0.00129970414295193" />
    </inertial>
    <visual>
      <origin xyz="0 0 0" rpy="0 0 0" />
      <geometry>
        <mesh filename="../meshes/friday/visual/head.obj" />
      </geometry>
    </visual>
    <visual>
      <origin xyz="0 0 0" rpy="0 0 0" />
      <geometry>
        <mesh filename="../meshes/friday/visual/head_back.obj" />
      </geometry>
    </visual>
    <visual>
      <origin xyz="0 0.098495703427300 0" rpy="0 0 0" />
      <geometry>
        <mesh filename="../meshes/friday/visual/head_eye.obj" />
      </geometry>
    </visual>
  </link>
  <joint name="head_2" type="revolute">
    <origin xyz="0 0.0379864298614376 0" rpy="0 0 0" />
    <parent link="head_1" />
    <child link="head_2" />
    <axis xyz="0 1 0" />
    <limit effort="87.0" lower="-1.4708" upper="1.4708" velocity="2.0" />
  </joint>
</robot>