<robot name="friday">
  <link name="waist_5">
    <inertial>
      <origin xyz="1.35732334303223E-05 0.135898614953202 -0.0188496042510568" rpy="0 0 0" />
      <mass value="12.474122580364" />
      <inertia ixx="0.109178941754524" ixy="-2.98129835492946E-05" ixz="-3.19150484404308E-06" iyy="0.107169406583023" iyz="-0.00214461668880564" izz="0.157827782829379" />
    </inertial>
    <visual>
      <origin xyz="0 0 0" rpy="0 0 0" />
      <geometry>
        <mesh filename="../meshes/friday/visual/body.obj" />
      </geometry>
    </visual>
    <visual>
      <origin xyz="0 -0.006322245945349 0" rpy="0 0 0" />
      <geometry>
        <mesh filename="../meshes/friday/visual/body_backpack.obj" />
      </geometry>
    </visual>
    <visual>
      <origin xyz="0 0.194843979673063 0" rpy="0 0 0" />
      <geometry>
        <mesh filename="../meshes/friday/visual/body_logo.obj" />
      </geometry>
    </visual>
    <collision>
      <origin xyz="0 0 0" rpy="0 0 0" />
      <geometry>
        <mesh filename="../meshes/friday/collision/compact_waist_5.obj" />
      </geometry>
    </collision>
  </link>
  <link name="left_arm_1">
    <inertial>
      <origin xyz="0.0681778315832787 0.0120221796894002 -0.0067812975431665" rpy="0 0 0" />
      <mass value="0.65274639829115" />
      <inertia ixx="0.000734648467001504" ixy="-3.62701010648506E-05" ixz="3.85551694833418E-05" iyy="0.000933899014758635" iyz="6.8080075629328E-06" izz="0.000897118604744115" />
    </inertial>
    <visual>
      <origin xyz="0 0 0" rpy="0 0 0" />
      <geometry>
        <mesh filename="../meshes/friday/visual/left_arm_1.obj" />
      </geometry>
    </visual>
  </link>
  <joint name="left_arm_1" type="revolute">
    <origin xyz="0.154235438602375 0.228025515459258 0" rpy="0 0 0" />
    <parent link="waist_5" />
    <child link="left_arm_1" />
    <axis xyz="-0.984807753012208 -0.173648177666932 0" />
    <limit effort="87.0" lower="-0.4236" upper="2.5180" velocity="2.0" />
  </joint>
  <link name="left_arm_2">
    <inertial>
      <origin xyz="0.00876610230499331 -0.0838600339221796 -0.000115821686215815" rpy="0 0 0" />
      <mass value="0.552470086721825" />
      <inertia ixx="0.000518419495011146" ixy="8.92509610843467E-06" ixz="-1.59111934775713E-06" iyy="0.00045867874968829" iyz="8.16013558251578E-06" izz="0.000543758567127829" />
    </inertial>
    <visual>
      <origin xyz="0 0 0" rpy="0 0 0" />
      <geometry>
        <mesh filename="../meshes/friday/visual/left_arm_2.obj" />
      </geometry>
    </visual>
    <collision>
      <origin xyz="0 0 0" rpy="0 0 0" />
      <geometry>
        <mesh filename="../meshes/friday/collision/compact_left_arm_2.obj" />
      </geometry>
    </collision>
  </link>
  <joint name="left_arm_2" type="revolute">
    <origin xyz="0.076891144603957 0.0135579833712227 0" rpy="0 0 0" />
    <parent link="left_arm_1" />
    <child link="left_arm_2" />
    <axis xyz="0 0 1" />
    <limit effort="87.0" lower="0.0" upper="2.2562" velocity="2.0" />
  </joint>
  <link name="left_arm_3">
    <inertial>
      <origin xyz="0.000140505415812536 -0.0647204132155317 -0.00150532371572329" rpy="0 0 0" />
      <mass value="0.641686932437179" />
      <inertia ixx="0.00131223395207345" ixy="5.88564128440786E-06" ixz="-1.35288724944641E-06" iyy="0.000496471588137728" iyz="-3.56318015097049E-05" izz="0.00132692863229049" />
    </inertial>
    <visual>
      <origin xyz="0 0 0" rpy="0 0 0" />
      <geometry>
        <mesh filename="../meshes/friday/visual/left_arm_3.obj" />
      </geometry>
    </visual>
    <collision>
      <origin xyz="0 -0.1 0.0" rpy="0 0 0" />
      <geometry>
				<box size="0.065 0.08 0.06" />
			</geometry>
    </collision>
  </link>
  <joint name="left_arm_3" type="revolute">
    <origin xyz="0.0100000000000251 -0.136500000000012 0" rpy="0 0 0" />
    <parent link="left_arm_2" />
    <child link="left_arm_3" />
    <axis xyz="0 1 0" />
    <limit effort="87.0" lower="-1.4708" upper="1.4708" velocity="2.0" />
  </joint>
  <link name="left_arm_4">
    <inertial>
      <origin xyz="-3.35287353436797E-14 -0.0459525747799207 -0.0136740346354466" rpy="0 0 0" />
      <mass value="0.467228497737904" />
      <inertia ixx="0.000771988413929587" ixy="1.77253719440116E-17" ixz="-1.0656151900853E-11" iyy="0.000278940154315871" iyz="4.81484142200182E-06" izz="0.000775309381777704" />
    </inertial>
    <visual>
      <origin xyz="0 0 0" rpy="0 0 0" />
      <geometry>
        <mesh filename="../meshes/friday/visual/left_arm_4.obj" />
      </geometry>
    </visual>
    <collision>
      <origin xyz="0 0 0" rpy="0 0 0" />
      <geometry>
        <mesh filename="../meshes/friday/collision/compact_left_arm_4.obj" />
      </geometry>
    </collision>
  </link>
  <joint name="left_arm_4" type="revolute">
    <origin xyz="0 -0.129999999999999 0.013499999998509" rpy="0 0 0" />
    <parent link="left_arm_3" />
    <child link="left_arm_4" />
    <axis xyz="-1 0 0" />
    <limit effort="87.0" lower="0.0" upper="2.1689" velocity="2.0" />
  </joint>
  <link name="left_arm_5">
    <inertial>
      <origin xyz="5.77929163333712E-05 -2.10908777993994E-05 0.0303745916212222" rpy="0 0 0" />
      <mass value="0.141645120451258" />
      <inertia ixx="0.000150674876659959" ixy="-9.98797795493656E-06" ixz="-9.93466740338049E-08" iyy="0.00015148916195091" iyz="8.09491425900871E-08" izz="7.9377319772219E-05" />
    </inertial>
    <visual>
      <origin xyz="0 0 0" rpy="0 0 0" />
      <geometry>
        <mesh filename="../meshes/friday/visual/left_arm_5.obj" />
      </geometry>
    </visual>
    <collision>
      <origin xyz="0 0 0" rpy="0 0 0" />
      <geometry>
        <mesh filename="../meshes/friday/collision/compact_left_arm_5.obj" />
      </geometry>
    </collision>
  </link>
  <joint name="left_arm_5" type="revolute">
    <origin xyz="0 -0.102599999999996 -0.013499999998509" rpy="1.5707963267949 0 0" />
    <parent link="left_arm_4" />
    <child link="left_arm_5" />
    <axis xyz="0 0 -1" />
    <limit effort="87.0" lower="-1.4708" upper="1.4708" velocity="2.0" />
  </joint>
  <link name="left_arm_6">
    <inertial>
      <origin xyz="-8.14545597854766E-05 7.51009215384403E-05 0.0117608666205666" rpy="0 0 0" />
      <mass value="0.0314621801352106" />
      <inertia ixx="7.82929735327746E-06" ixy="1.1061250640138E-08" ixz="1.46345904053749E-08" iyy="8.7132179616215E-06" iyz="-7.15856215622018E-09" izz="7.73497403513724E-06" />
    </inertial>
    <visual>
      <origin xyz="0 0 0" rpy="0 0 0" />
      <geometry>
        <mesh filename="../meshes/friday/visual/left_arm_6.obj" />
      </geometry>
    </visual>
  </link>
  <joint name="left_arm_6" type="revolute">
    <origin xyz="0 0 0.111999999999982" rpy="0 0 0" />
    <parent link="left_arm_5" />
    <child link="left_arm_6" />
    <axis xyz="0 1 0" />
    <limit effort="87.0" lower="-0.9472" upper="0.9472" velocity="2.0" />
  </joint>
  <link name="left_arm_7">
    <inertial>
      <origin xyz="0.0015564769305858 0.0031171837162328 -0.0509003091661051" rpy="0 0 0" />
      <mass value="0.131752288131971" />
      <inertia ixx="7.77640623933446E-05" ixy="-8.79352768144738E-07" ixz="-8.87560258478892E-07" iyy="3.25935847362588E-05" iyz="6.93151713655908E-06" izz="5.59108691824527E-05" />
    </inertial>
    <visual>
      <origin xyz="0 0 0" rpy="0 0 0" />
      <geometry>
        <mesh filename="../meshes/friday/visual/left_arm_7.obj" />
      </geometry>
    </visual>
    <collision>
      <origin xyz="0 0 0" rpy="0 0 0" />
      <geometry>
        <mesh filename="../meshes/friday/collision/compact_left_arm_7.obj" />
      </geometry>
    </collision>
  </link>
  <joint name="left_arm_7" type="revolute">
    <origin xyz="0 0 0.040000000000001" rpy="3.14159265358979 0 3.14159265358979" />
    <parent link="left_arm_6" />
    <child link="left_arm_7" />
    <axis xyz="1 0 0" />
    <limit effort="87.0" lower="-0.6854" upper="0.6854" velocity="2.0" />
  </joint>
  <link name="ball_link">
      <visual>
      <material name="red">
          <color rgba="1 0 0 1"/>
      </material>

      <geometry>
          <sphere radius="0.01"/>
      </geometry>
      </visual>
  </link>
  <joint name="ball_joint" type="fixed">
      <origin rpy="0.0 0.0 0.0" xyz="0.09566 0 -0.021" />
      <parent link="left_arm_7"/>
      <child link="ball_link"/>
  </joint>
</robot>