<?xml version="1.0" ?>
<robot name="fr3_gripper">
  <material name="Silver">
    <color rgba="1.0 1.0 1.0 1.0" />
  </material>
  <material name="Black">
    <color rgba="0.0 0.0 0.0 1.0" />
  </material>
  <material name="Chrome">
    <color rgba="0.0 0.0 0.0 1.0" />
  </material>
  <material name="DarkGrey">
    <color rgba="0.33 0.33 0.33 1.0" />
  </material>
  <material name="Grey">
    <color rgba="0.55 0.55 0.55 0.8" />
  </material>
  <material name="OpaqueGreen">
    <color rgba="0.0 1.0 0.0 0.2" />
  </material>
  <material name="OpaqueRed">
    <color rgba="1.0 0.0 0.0 0.2" />
  </material>

  <link name="link0">
    <visual>
      <geometry>
        <mesh filename="../meshes/panda/link0.dae" />
      </geometry>
    </visual>
    <collision>
      <geometry>
        <mesh filename="../meshes/panda/link0.obj" scale="1.0 1.0 1.0"/>
      </geometry>
    </collision>
  </link>

  <joint name="joint1" type="revolute">
    <safety_controller k_position="100.0" k_velocity="40.0" soft_lower_limit="-2.8973" soft_upper_limit="2.8973" />
    <origin rpy="0 0 0" xyz="0 0 0.333" />
    <parent link="link0" />
    <child link="link1" />
    <axis xyz="0 0 1" />
    <limit effort="87" lower="-2.3093" upper="2.3093" velocity="2.0"/>
    <!-- <limit effort="87" lower="-2.3093" upper="2.3093" velocity="2.62"/> -->
  </joint>

  <link name="link1">
    <visual>
      <geometry>
        <mesh filename="../meshes/panda/link1.dae" />
      </geometry>
    </visual>
    <collision>
      <geometry>
        <mesh filename="../meshes/panda/link1.obj" scale="1.0 1.0 1.0"/>
      </geometry>
    </collision>
  </link>

  <joint name="joint2" type="revolute">
    <safety_controller k_position="100.0" k_velocity="40.0" soft_lower_limit="-1.7628" soft_upper_limit="1.7628" />
    <origin rpy="-1.57079632679 0 0" xyz="0 0 0" />
    <parent link="link1" />
    <child link="link2" />
    <axis xyz="0 0 1" />
    <limit effort="87.0" lower="-1.5133" upper="1.5133" velocity="1.0" />
    <!-- <limit effort="87.0" lower="-1.5133" upper="1.5133" velocity="2.62" /> -->
  </joint>

  <link name="link2">
    <visual>
      <geometry>
        <mesh filename="../meshes/panda/link2.dae" />
      </geometry>
    </visual>
    <collision>
      <geometry>
        <mesh filename="../meshes/panda/link2.obj" scale="1.0 1.0 1.0"/>
      </geometry>
    </collision>
  </link>

  <joint name="joint3" type="revolute">
    <safety_controller k_position="100.0" k_velocity="40.0" soft_lower_limit="-2.8973" soft_upper_limit="2.8973" />
    <origin rpy="1.57079632679 0 0" xyz="0 -0.316 0" />
    <parent link="link2" />
    <child link="link3" />
    <axis xyz="0 0 1" />
    <limit effort="87.0" lower="-2.4937" upper="2.4937" velocity="1.5" />
    <!-- <limit effort="87.0" lower="-2.4937" upper="2.4937" velocity="2.62" /> -->
  </joint>

  <link name="link3">
    <visual>
      <geometry>
        <mesh filename="../meshes/panda/link3.dae" />
      </geometry>
    </visual>
    <collision>
      <geometry>
        <mesh filename="../meshes/panda/link3.obj" scale="1.0 1.0 1.0"/>
      </geometry>
    </collision>
  </link>

  <joint name="joint4" type="revolute">
    <safety_controller k_position="100.0" k_velocity="40.0" soft_lower_limit="-3.0718" soft_upper_limit="0.0175" />
    <origin rpy="1.57079632679 0 0" xyz="0.0825 0 0" />
    <parent link="link3" />
    <child link="link4" />
    <axis xyz="0 0 1" />
    <limit effort="87.0" lower="-2.7478" upper="-0.4461" velocity="1.25" />
    <!-- <limit effort="87.0" lower="-2.7478" upper="-0.4461" velocity="2.62" /> -->
  </joint>

  <link name="link4">
    <visual>
      <geometry>
        <mesh filename="../meshes/panda/link4.dae" />
      </geometry>
    </visual>
    <collision>
      <geometry>
        <mesh filename="../meshes/panda/link4.obj" scale="1.0 1.0 1.0"/>
      </geometry>
    </collision>
  </link>

  <joint name="joint5" type="revolute">
      <safety_controller k_position="100.0" k_velocity="40.0" soft_lower_limit="-2.8973" soft_upper_limit="2.8973" />
      <origin rpy="-1.57079632679 0 0" xyz="-0.0825 0.384 0" />
      <parent link="link4" />
      <child link="link5" />
      <axis xyz="0 0 1" />
      <limit effort="12.0" lower="-2.48" upper="2.48" velocity="3.0" />
      <!-- <limit effort="12.0" lower="-2.48" upper="2.48" velocity="5.26" /> -->
  </joint>

  <link name="link5">
    <visual>
      <geometry>
        <mesh filename="../meshes/panda/link5.dae" />
      </geometry>
    </visual>
    <collision>
      <geometry>
        <mesh filename="../meshes/panda/link5.obj" scale="1.0 1.0 1.0"/>
      </geometry>
    </collision>
  </link>

  <joint name="joint6" type="revolute">
    <safety_controller k_position="100.0" k_velocity="40.0" soft_lower_limit="-0.0175" soft_upper_limit="3.7525" />
    <origin rpy="1.57079632679 0 0" xyz="0 0 0" />
    <parent link="link5" />
    <child link="link6" />
    <axis xyz="0 0 1" />
    <limit effort="12.0" lower="0.8521" upper="4.2094" velocity="1.5" />
    <!-- <limit effort="12.0" lower="0.8521" upper="4.2094" velocity="4.18" /> -->
  </joint>

  <link name="link6">
    <visual>
      <geometry>
        <mesh filename="../meshes/panda/link6.dae" />
      </geometry>
    </visual>
    <collision>
      <geometry>
        <mesh filename="../meshes/panda/link6.obj" scale="1.0 1.0 1.0"/>
      </geometry>
    </collision>
  </link>

  <joint name="joint7" type="revolute">
    <safety_controller k_position="100.0" k_velocity="40.0" soft_lower_limit="-2.8973" soft_upper_limit="2.8973" />
    <origin rpy="1.57079632679 0 0" xyz="0.088 0 0" />
    <parent link="link6" />
    <child link="link7" />
    <axis xyz="0 0 1" />
    <limit effort="12.0" lower="-2.6895" upper="2.6895" velocity="3.0" />
    <!-- <limit effort="12.0" lower="-2.6895" upper="2.6895" velocity="5.26" /> -->
  </joint>

  <link name="link7">
    <visual>
      <geometry>
        <mesh filename="../meshes/panda/link7.dae" />
      </geometry>
    </visual>
    <collision>
      <geometry>
        <mesh filename="../meshes/panda/link7.obj" scale="1.0 1.0 1.0"/>
      </geometry>
    </collision>
  </link>

  <!-- ft_sensor_mount -->
  <joint name="ft_sensor_and_mount_joint" type="fixed">
    <parent link="link7" />
    <child link="ft_sensor_and_mount_link" />
    <origin rpy="0 0 0.784602" xyz="0 0 0.107" /> 
  </joint>


  <link name="ft_sensor_and_mount_link">
    <visual>
      <origin xyz="0 0 0.015" rpy="0 0 0" />
      <geometry>
        <cylinder length="0.03" radius="0.04"/>
      </geometry>
      <material name="Grey" />
      <origin xyz="0 0 0.04" rpy="0 0 0" />
        <geometry>
            <mesh filename="package://holiday_robot_descriptions/assets/object/visual/adin_ft_sensor.obj" scale="0.001 0.001 0.001"/>
        </geometry>
        <material name="Black" />
    </visual>
    <collision>
      <origin xyz="0 0 0.015" rpy="0 0 0" />
      <geometry>
        <cylinder length="0.03" radius="0.04"/>
      </geometry>
      <material name="Grey" />
      <origin xyz="0 0 0.04" rpy="0 0 0" />
        <geometry>
            <mesh filename="package://holiday_robot_descriptions/assets/object/collision/adin_ft_sensor.obj" scale="0.001 0.001 0.001"/>
        </geometry>
        <material name="Black" />
    </collision>
  </link>

  <!-- hand mount -->
  <joint name="hand_mount_joint" type="fixed">
    <parent link="ft_sensor_and_mount_link" />
    <child link="hand_mount_link" />
    <origin rpy="0 0 0" xyz="0 0 0.05" /> 
  </joint>

  <link name="hand_mount_link">
    <visual>
      <origin xyz="0 0 0.015" rpy="0 0 0" />
      <geometry>
        <cylinder length="0.025" radius="0.03"/>
      </geometry>
      <material name="Grey" />
    </visual>
    <collision>
      <origin xyz="0 0 0.015" rpy="0 0 0" />
      <geometry>
        <cylinder length="0.025" radius="0.03"/>
      </geometry>
      <material name="Grey" />
    </collision>
  </link>

  <joint name="panda_hand_joint" type="fixed">
    <parent link="hand_mount_link" />
    <child link="panda_hand" />
    <origin rpy="0 0 -1.5708" xyz="0 0 0.025" />
  </joint>

  <link name="panda_hand">
    <visual>
      <geometry>
        <mesh filename="../meshes/panda/hand.dae" />
      </geometry>
    </visual>
    <collision>
      <geometry>
        <mesh filename="../meshes/panda/hand.obj" />
      </geometry>
    </collision>
  </link>

  <link name="panda_hand_tcp"/>
  <joint name="panda_hand_tcp_joint" type="fixed">
    <origin rpy="0 0 0" xyz="0 0 0.1034"/>
    <parent link="panda_hand"/>
    <child link="panda_hand_tcp"/>
  </joint>
  <link name="ball_link">
    <visual>
      <material name="red">
        <color rgba="1 0 0 1"/>
      </material>

      <geometry>
        <sphere radius="0.01"/>
      </geometry>
    </visual>
  </link>

  <joint name="ball_joint" type="fixed">
    <origin rpy="0.0 0.0 0.0" xyz="0 0 0.02866" />
    <parent link="panda_hand_tcp"/>
    <child link="ball_link"/>
  </joint>



  <joint name="panda_finger_joint1" type="prismatic">
    <parent link="panda_hand" />
    <child link="panda_leftfinger" />
    <origin rpy="0 0 0" xyz="0 0 0.0584" />
    <axis xyz="0 1 0" />
    <limit effort="20" lower="0.0" upper="0.04" velocity="0.2" />
  </joint>

  <link name="panda_leftfinger">
    <visual>
      <geometry>
        <mesh filename="../meshes/panda/finger.dae" />
      </geometry>
    </visual>
    <collision>
      <geometry>
        <mesh filename="../meshes/panda/finger.obj" />
      </geometry>
    </collision>    
  </link>

  <joint name="panda_finger_joint2" type="prismatic">
      <parent link="panda_hand" />
      <child link="panda_rightfinger" />
      <origin rpy="0 0 0" xyz="0 0 0.0584" />
      <axis xyz="0 -1 0" />
      <limit effort="20" lower="0.0" upper="0.04" velocity="0.2" />
      <!-- <mimic joint="panda_finger_joint1" /> -->
  </joint>

  <link name="panda_rightfinger">
    <visual>
      <origin rpy="0 0 3.14159265359" xyz="0 0 0" />
      <geometry>
          <mesh filename="../meshes/panda/finger.dae" />
      </geometry>
    </visual>
    <collision>
        <origin rpy="0 0 3.14159265359" xyz="0 0 0" />
        <geometry>
          <mesh filename="../meshes/panda/finger.obj" />
        </geometry>
    </collision>   
  </link>  

  <!--Used for calculating pose and Jacobian.
  Joint connects hand to dummy link located at midpoint between centers of original fingerpads (when fingers are mirrored).-->

  <joint name="panda_fingertip_centered_joint" type="fixed">
      <parent link="panda_hand"/>
      <child link="panda_fingertip_centered"/>
      <origin rpy="0 0 0" xyz="0 0 0.1034"/>
  </joint>

  <link name="panda_fingertip_centered">
    <inertial>
      <origin rpy="0 0 0" xyz="0 0 0"/>
      <mass value="1.0e-6"/>
      <inertia ixx="1.0e-09" ixy="0" ixz="0" iyy="1.0e-09" iyz="0" izz="1.0e-09"/>
    </inertial>
  </link>

</robot>